Workbook

Sheet 00_说明与口径
A1: A款-防滑鼻托套装(2对装)｜退货分析
A3: 一、清洗漏斗
A4: 步骤 | B4: 规则 | C4: 剩下
A5: 原始行数 | B5: 导出文件的全部行 | C5: 371
A6: 只留退货 | B6: 换货用的是另一套原因码，必须先筛掉 | C6: 357
A7: 限定范围 | B7: 产品=A款-防滑鼻托套装(2对装) · 站点=全部 | C7: 357
A8: 剔掉与产品无关的 | B8: 物流 / 客户改主意 / 没给原因，共 10 类 | C8: 283
A9: 留下且有原话 | B9: 没写字的、只有平台套话的（7 条）都去掉 | C9: 94
A11: 二、口径
A12: 退货明细行 | B12: 本次范围内的退货行数 | C12: 357
A13: 退货订单 | B13: 同一订单只算一次 | C13: 332
A14: 写了原因的占比 | B14: 写了字的 ÷ 明细行 | C14: 0.283
A15: ⚠ 编码损坏 | B15: 原话里出现 2 处字面的 '??'。非英文字符在导出时就丢了，救不回来。要求重新导出为 UTF-8，不要拿坏掉的原话去打标。
A17: 三、「该谁改」怎么判
A18: 产品的事 | B18: 客户拿「产品该做到的事」当参照 → 改结构、改材料、大货抽检 | C18: 产品 · 研发/品控
A19: 页面的事 | B19: 客户拿「你告诉他的话」当参照 → 校准规格表、收敛宣称、补图文 | C19: 运营 · 页面
A20: 客户自己选错 | B20: 客户自己认了 → 用来算能挽回多少，优化换档引导 | C20: 不算产品问题
A21: 不该买这款 | B21: 产品没坏、页面没错，是这个人不该买这一款 → 重新说清楚卖给谁 | C21: 品牌 · 定位
A22: 说不清 | B22: 原话信息不够 → 不拿来做决定，但占比本身是结论 | C22: —
A23: 其他 | B23: 跟产品和页面都无关 → 包装、到货状态等 | C23: —
A25: 四、这批数据答不了什么
B26: 「说不清该谁改」占 33%（31 条）。这不是打标失败，是平台的退货表单没给客户说清楚的地方——大量原话只有「fit」「case」「too thin」这样的残句。没有线索一律判说不清，不替客户猜。要压低这个比例，得在售后工单或退货问卷里加一道开放题。
B27: 这个品类的平台原因码里没有「太高 / 太矮」这种带方向的码，所以「两头是否对称」只能在原话那一层算（31 条），没有全部退货那一层做对照。
B28: 宽度那一项只有 9 条，判「一边倒」靠的是 9 比 0 这个形状，不是样本量。充电盒收纳 5 条全在 2.5mm，同理。都应该在下一轮数据里再看一眼。
B29: 硅胶软硬 3 硬 1 软、同款批次硬度不同 1 条，样本太少，只写进了待验证，没有进结论。
B30: 2 条德国站原话里有 1 条在导出时被弄坏了（变音字母变成了问号），意思还能认出来，照常打了标；德语的「多严重」没有单独校准过，这 2 条都按中度算。以后要是德国站多起来，必须重新导出为 UTF-8。
B31: 多严重靠语气和后果判：明说东西掉了、坏了、生气了的算严重；只说高了矮了的算中度；自己认了选错的算轻度。
B32: 末期数据没有回流完整的月份不要拿来看走势。

Sheet 01_打标明细
A1: 序号 | B1: 记录编号 | C1: 订单号 | D1: 站点 | E1: 规格 | F1: 月份 | G1: 平台原因码 | H1: 原话 | I1: 哪件事_大类 | J1: 哪件事_细项 | K1: 谁在说 | L1: 什么情况下 | M1: 过程感受 | N1: 该谁改 | O1: 多严重 | P1: 能否挽回
A2: 1 | B2: SAMPLE-EV-0003 | C2: SAMPLE-ORDER-9106 | D2: US | E2: 大号款-2.5mm | F2: 2026-01 | G2: NOT_AS_DESCRIBED | H2: followed the size recommendation on the page, 2.5 is too high for me | I2: 高度与贴合 | J2: 整体高度:偏高; 选档指引 | K2: 照页面指引选的 | N2: 页面的事 | O2: 中度 | P2: 否
A3: 2 | B3: SAMPLE-EV-0008 | C3: SAMPLE-ORDER-9388 | D3: US | E3: 大号款-2.5mm | F3: 2026-06 | G3: QUALITY_UNACCEPTABLE | H3: not worth the price for four bits of silicone | I3: 综合质量 | J3: 值不值 | N3: 说不清 | O3: 轻度 | P3: 否
A4: 3 | B4: SAMPLE-EV-0009 | C4: SAMPLE-ORDER-3558 | D4: US | E4: 标准款-2.5mm | F4: 2026-08 | G4: QUALITY_UNACCEPTABLE | H4: second order from the same listing. These pads are noticeably harder than my first set | I4: 综合质量 | J4: 同款批次一致性; 硅胶软硬:偏硬 | K4: 长期佩戴 | N4: 产品的事 | O4: 中度 | P4: 否
A5: 4 | B5: SAMPLE-EV-0014 | C5: SAMPLE-ORDER-1360 | D5: US | E5: 标准款-2.5mm | F5: 2026-01 | G5: DEFECTIVE | H5: not good | I5: 综合质量 | J5: 质量(泛指) | N5: 说不清 | O5: 中度 | P5: 否
A6: 5 | B6: SAMPLE-EV-0021 | C6: SAMPLE-ORDER-3815 | D6: US | E6: 大号款-1.8mm | F6: 2026-02 | G6: NOT_AS_DESCRIBED | H6: fit | I6: 高度与贴合 | J6: 合适度(没说方向) | N6: 说不清 | O6: 轻度 | P6: 否
A7: 6 | B7: SAMPLE-EV-0024 | C7: SAMPLE-ORDER-5463 | D7: US | E7: 标准款-2.5mm | F7: 2026-02 | G7: NOT_AS_DESCRIBED | H7: Listing says sweat proof adhesive. Came off after one gym session | I7: 防滑与固定 | J7: 背胶牢固度; 防滑宣称兑现度 | L7: 运动出汗 | N7: 页面的事 | O7: 严重 | P7: 否
A8: 7 | B8: SAMPLE-EV-0026 | C8: SAMPLE-ORDER-7507 | D8: US | E8: 标准款-2.5mm | F8: 2026-03 | G8: DEFECTIVE | H8: Sits too high. Took them off after an hour | I8: 高度与贴合 | J8: 整体高度:偏高 | M8: 佩戴舒适度 | N8: 说不清 | O8: 中度 | P8: 否
A9: 8 | B9: SAMPLE-EV-0027 | C9: SAMPLE-ORDER-0711 | D9: US | E9: 标准款-1.8mm | F9: 2026-01 | G9: NOT_AS_DESCRIBED | H9: very nice idea but I don't want anything glued to my glasses | I9: 综合质量 | J9: 贴片式形态(这一款特有); 与预期(泛指) | N9: 不该买这款 | O9: 轻度 | P9: 否
A10: 9 | B10: SAMPLE-EV-0029 | C10: SAMPLE-ORDER-4846 | D10: US | E10: 标准款-2.5mm | F10: 2026-06 | G10: NOT_AS_DESCRIBED | H10: even 2.5 is not enough height for me | I10: 高度与贴合 | J10: 整体高度:偏矮 | N10: 说不清 | O10: 中度 | P10: 否
A11: 10 | B11: SAMPLE-EV-0030 | C11: SAMPLE-ORDER-0951 | D11: US | E11: 标准款-2.5mm | F11: 2026-03 | G11: NOT_AS_DESCRIBED | H11: page says pick 2.5 if glasses slide. They did stop sliding but now sit too high and the photos are all tilted up | I11: 高度与贴合 | J11: 整体高度:偏高; 选档指引; 摄像头视角 | K11: 照页面指引选的 | M11: 安心感(夸) | N11: 页面的事 | O11: 中度 | P11: 否
A12: 11 | B12: SAMPLE-EV-0032 | C12: SAMPLE-ORDER-4163 | D12: US | E12: 大号款-2.5mm | F12: 2026-01 | G12: ORDERED_WRONG_ITEM | H12: 2.5 was too much, swapping for the 1.8 | I12: 高度与贴合 | J12: 整体高度:偏高 | K12: 计划换档 | N12: 说不清 | O12: 轻度 | P12: 是
A13: 12 | B13: SAMPLE-EV-0047 | C13: SAMPLE-ORDER-0203 | D13: US | E13: 标准款-2.5mm | F13: 2026-02 | G13: NOT_AS_DESCRIBED | H13: The page told me to go 2.5 for a low bridge. Too much lift | I13: 高度与贴合 | J13: 整体高度:偏高; 选档指引 | K13: 照页面指引选的 | N13: 页面的事 | O13: 中度 | P13: 否
A14: 13 | B14: SAMPLE-EV-0048 | C14: SAMPLE-ORDER-0503 | D14: US | E14: 标准款-2.5mm | F14: 2026-01 | G14: DEFECTIVE | H14: They don't work for me. Glasses still slide when I run | I14: 防滑与固定 | J14: 防滑效果(泛指) | L14: 运动出汗 | N14: 产品的事 | O14: 严重 | P14: 否
A15: 14 | B15: SAMPLE-EV-0050 | C15: SAMPLE-ORDER-4821 | D15: US | E15: 大号款-2.5mm | F15: 2026-07 | G15: NOT_AS_DESCRIBED | H15: too high on nose, as recommended size | I15: 高度与贴合 | J15: 整体高度:偏高; 选档指引 | K15: 照页面指引选的 | N15: 页面的事 | O15: 中度 | P15: 否
A16: 15 | B16: SAMPLE-EV-0051 | C16: SAMPLE-ORDER-8622 | D16: US | E16: 大号款-2.5mm | F16: 2026-04 | G16: NOT_AS_DESCRIBED | H16: thickness | I16: 高度与贴合 | J16: 合适度(没说方向) | N16: 说不清 | O16: 轻度 | P16: 否
A17: 16 | B17: SAMPLE-EV-0056 | C17: SAMPLE-ORDER-8107 | D17: US | E17: 大号款-1.8mm | F17: 2026-02 | G17: NOT_COMPATIBLE | H17: not for Skyler model even though title says fits all | I17: 兼容与收纳 | J17: 机型适配; 兼容宣称兑现度 | N17: 页面的事 | O17: 中度 | P17: 否
A18: 17 | B18: SAMPLE-EV-0063 | C18: SAMPLE-ORDER-6414 | D18: US | E18: 标准款-1.8mm | F18: 2026-02 | G18: NOT_AS_DESCRIBED | H18: didn't fit | I18: 高度与贴合 | J18: 合适度(没说方向) | N18: 说不清 | O18: 轻度 | P18: 否
A19: 18 | B19: SAMPLE-EV-0067 | C19: SAMPLE-ORDER-1287 | D19: US | E19: 标准款-1.8mm | F19: 2026-05 | G19: NOT_COMPATIBLE | H19: Great idea and really comfortable, but the glasses stopped charging in the case | I19: 兼容与收纳 | J19: 装上后充电 | L19: 放回充电盒时 | M19: 佩戴舒适度(夸) | N19: 产品的事 | O19: 中度 | P19: 否
A20: 19 | B20: SAMPLE-EV-0070 | C20: SAMPLE-ORDER-5169 | D20: US | E20: 大号款-1.8mm | F20: 2026-05 | G20: NOT_AS_DESCRIBED | H20: color is not what the picture shows | I20: 材质与做工 | J20: 颜色与图片一致 | N20: 页面的事 | O20: 中度 | P20: 否
A21: 20 | B21: SAMPLE-EV-0078 | C21: SAMPLE-ORDER-9741 | D21: US | E21: 标准款-1.8mm | F21: 2026-07 | G21: NOT_AS_DESCRIBED | H21: pad is wider than the original nose piece, edges stick out and look ugly | I21: 高度与贴合 | J21: 宽度与覆盖:偏宽 | K21: 原装鼻托 | M21: 外观体面度 | N21: 产品的事 | O21: 中度 | P21: 否
A22: 21 | B22: SAMPLE-EV-0084 | C22: SAMPLE-ORDER-6590 | D22: US | E22: 标准款-2.5mm | F22: 2026-06 | G22: NOT_AS_DESCRIBED | H22: Pads are too thick, glasses sit way too high on my face | I22: 高度与贴合 | J22: 整体高度:偏高 | N22: 说不清 | O22: 中度 | P22: 否
A23: 22 | B23: SAMPLE-EV-0088 | C23: SAMPLE-ORDER-2436 | D23: US | E23: 标准款-1.8mm | F23: 2026-01 | G23: NOT_AS_DESCRIBED | H23: too short | I23: 高度与贴合 | J23: 整体高度:偏矮 | N23: 说不清 | O23: 轻度 | P23: 否
A24: 23 | B24: SAMPLE-EV-0091 | C24: SAMPLE-ORDER-7769 | D24: US | E24: 大号款-1.8mm | F24: 2026-06 | G24: QUALITY_UNACCEPTABLE | H24: too wide for the nose area, sticks out past the frame | I24: 高度与贴合 | J24: 宽度与覆盖:偏宽 | N24: 产品的事 | O24: 中度 | P24: 否
A25: 24 | B25: SAMPLE-EV-0098 | C25: SAMPLE-ORDER-4895 | D25: US | E25: 标准款-2.5mm | F25: 2026-03 | G25: QUALITY_UNACCEPTABLE | H25: looked like the bag had been opened before, pads had lint on them | I25: 综合质量 | J25: 新旧状态 | M25: 收货第一印象 | N25: 产品的事 | O25: 严重 | P25: 否
A26: 25 | B26: SAMPLE-EV-0101 | C26: SAMPLE-ORDER-7326 | D26: US | E26: 标准款-1.8mm | F26: 2026-08 | G26: NOT_COMPATIBLE | H26: does not fit the Headliner frame, nose area is a different shape | I26: 兼容与收纳 | J26: 机型适配 | N26: 说不清 | O26: 中度 | P26: 否
A27: 26 | B27: SAMPLE-EV-0102 | C27: SAMPLE-ORDER-3588 | D27: US | E27: 大号款-2.5mm | F27: 2026-03 | G27: NOT_AS_DESCRIBED | H27: too wide, visible from the front, embarrassing in meetings | I27: 高度与贴合 | J27: 宽度与覆盖:偏宽 | M27: 外观体面度 | N27: 产品的事 | O27: 严重 | P27: 否
A28: 27 | B28: SAMPLE-EV-0105 | C28: SAMPLE-ORDER-9682 | D28: US | E28: 标准款-2.5mm | F28: 2026-05 | G28: NOT_AS_DESCRIBED | H28: Says 2 pairs. Got 3 single pads, not even 2 full pairs | I28: 非产品因素 | J28: 发货准确 | M28: 收货第一印象 | N28: 其他 | O28: 中度 | P28: 否
A29: 28 | B29: SAMPLE-EV-0110 | C29: SAMPLE-ORDER-9962 | D29: US | E29: 标准款-1.8mm | F29: 2026-02 | G29: DEFECTIVE | H29: glue fails when I sweat, pads slide around on the frame | I29: 防滑与固定 | J29: 出汗时防滑 | L29: 运动出汗 | N29: 产品的事 | O29: 严重 | P29: 否
A30: 29 | B30: SAMPLE-EV-0114 | C30: SAMPLE-ORDER-6013 | D30: US | E30: 大号款-1.8mm | F30: 2026-08 | G30: NOT_AS_DESCRIBED | H30: not tall enough for a flat nose bridge | I30: 高度与贴合 | J30: 整体高度:偏矮 | N30: 说不清 | O30: 中度 | P30: 否
A31: 30 | B31: SAMPLE-EV-0117 | C31: SAMPLE-ORDER-1111 | D31: US | E31: 标准款-2.5mm | F31: 2026-07 | G31: NOT_COMPATIBLE | H31: changes the camera angle, every video is aimed too high | I31: 兼容与收纳 | J31: 摄像头视角 | N31: 产品的事 | O31: 中度 | P31: 否
A32: 31 | B32: SAMPLE-EV-0125 | C32: SAMPLE-ORDER-5757 | D32: US | E32: 标准款-1.8mm | F32: 2026-08 | G32: DEFECTIVE | H32: not enough lift, lashes still hit the lens | I32: 高度与贴合 | J32: 整体高度:偏矮 | N32: 说不清 | O32: 中度 | P32: 否
A33: 32 | B33: SAMPLE-EV-0129 | C33: SAMPLE-ORDER-0675 | D33: US | E33: 标准款-1.8mm | F33: 2026-07 | G33: NOT_AS_DESCRIBED | H33: listing says 2 pairs, only 1 pair in the bag | I33: 非产品因素 | J33: 发货准确 | M33: 收货第一印象 | N33: 其他 | O33: 中度 | P33: 否
A34: 33 | B34: SAMPLE-EV-0130 | C34: SAMPLE-ORDER-8566 | D34: US | E34: 标准款-1.8mm | F34: 2026-07 | G34: ORDERED_WRONG_ITEM | H34: need thicker. Will order the 2.5 | I34: 高度与贴合 | J34: 整体高度:偏矮 | K34: 计划换档 | N34: 说不清 | O34: 轻度 | P34: 是
A35: 34 | B35: SAMPLE-EV-0131 | C35: SAMPLE-ORDER-5078 | D35: US | E35: 标准款-1.8mm | F35: 2026-06 | G35: DEFECTIVE | H35: adhesive gave out the first time I wore them, one pad is gone | I35: 防滑与固定 | J35: 背胶牢固度 | L35: 第一次用就出问题 | N35: 产品的事 | O35: 严重 | P35: 否
A36: 35 | B36: SAMPLE-EV-0135 | C36: SAMPLE-ORDER-1756 | D36: US | E36: 标准款-2.5mm | F36: 2026-07 | G36: NOT_AS_DESCRIBED | H36: Listing said low nose bridge should pick 2.5mm. I did. Way too tall, frames float above my eyebrows | I36: 高度与贴合 | J36: 整体高度:偏高; 选档指引 | K36: 照页面指引选的 | M36: 外观体面度 | N36: 页面的事 | O36: 中度 | P36: 否
A37: 36 | B37: SAMPLE-EV-0136 | C37: SAMPLE-ORDER-2480 | D37: US | E37: 标准款-1.8mm | F37: 2026-02 | G37: NOT_AS_DESCRIBED | H37: even the thin one raises the glasses too much for me | I37: 高度与贴合 | J37: 整体高度:偏高 | N37: 说不清 | O37: 中度 | P37: 否
A38: 37 | B38: SAMPLE-EV-0145 | C38: SAMPLE-ORDER-7573 | D38: US | E38: 标准款-1.8mm | F38: 2026-01 | G38: NOT_AS_DESCRIBED | H38: thought these were screw in replacement nose pads. These are just stickers | I38: 综合质量 | J38: 贴片式形态(这一款特有); 与预期(泛指) | N38: 不该买这款 | O38: 中度 | P38: 否
A39: 38 | B39: SAMPLE-EV-0148 | C39: SAMPLE-ORDER-9167 | D39: US | E39: 标准款-2.5mm | F39: 2026-05 | G39: DEFECTIVE | H39: lifts the frame so much the camera now points at the ceiling | I39: 高度与贴合 | J39: 整体高度:偏高; 摄像头视角 | N39: 产品的事 | O39: 中度 | P39: 否
A40: 39 | B40: SAMPLE-EV-0150 | C40: SAMPLE-ORDER-1547 | D40: US | E40: 标准款-1.8mm | F40: 2026-08 | G40: NOT_COMPATIBLE | H40: I have the large frame and bought standard. My mistake, reordering the large version | I40: 兼容与收纳 | J40: 机型适配 | K40: 已换档复购 | N40: 客户自己选错 | O40: 轻度 | P40: 是
...

Sheet 02_标签统计
A1: 客户在说什么（一条原话可以说到好几件事，合计 > 94）｜进排名的门槛 ≥3
A3: 大类 | B3: 细项 | C3: 提到的条数 | D3: 占 94 条
A4: 高度与贴合 | B4: — 小计 | C4: =COUNTIF('01_打标明细'!$I$2:$I$95,"高度与贴合") | D4: =C4/94
B5: 整体高度 | C5: =SUMPRODUCT(--ISNUMBER(SEARCH("整体高度",'01_打标明细'!$J$2:$J$95))) | D5: =C5/94
B6: 宽度与覆盖 | C6: =SUMPRODUCT(--ISNUMBER(SEARCH("宽度与覆盖",'01_打标明细'!$J$2:$J$95))) | D6: =C6/94
B7: 选档指引 | C7: =SUMPRODUCT(--ISNUMBER(SEARCH("选档指引",'01_打标明细'!$J$2:$J$95))) | D7: =C7/94
B8: 合适度(没说方向) | C8: =SUMPRODUCT(--ISNUMBER(SEARCH("合适度(没说方向)",'01_打标明细'!$J$2:$J$95))) | D8: =C8/94
B9: 防滑效果(泛指) | C9: =SUMPRODUCT(--ISNUMBER(SEARCH("防滑效果(泛指)",'01_打标明细'!$J$2:$J$95))) | D9: =C9/94
B10: 摄像头视角 | C10: =SUMPRODUCT(--ISNUMBER(SEARCH("摄像头视角",'01_打标明细'!$J$2:$J$95))) | D10: =C10/94
A11: 防滑与固定 | B11: — 小计 | C11: =COUNTIF('01_打标明细'!$I$2:$I$95,"防滑与固定") | D11: =C11/94
B12: 整体高度 | C12: =SUMPRODUCT(--ISNUMBER(SEARCH("整体高度",'01_打标明细'!$J$2:$J$95))) | D12: =C12/94
B13: 背胶牢固度 | C13: =SUMPRODUCT(--ISNUMBER(SEARCH("背胶牢固度",'01_打标明细'!$J$2:$J$95))) | D13: =C13/94
B14: 防滑效果(泛指) | C14: =SUMPRODUCT(--ISNUMBER(SEARCH("防滑效果(泛指)",'01_打标明细'!$J$2:$J$95))) | D14: =C14/94
B15: 防滑宣称兑现度 | C15: =SUMPRODUCT(--ISNUMBER(SEARCH("防滑宣称兑现度",'01_打标明细'!$J$2:$J$95))) | D15: =C15/94
B16: 出汗时防滑 | C16: =SUMPRODUCT(--ISNUMBER(SEARCH("出汗时防滑",'01_打标明细'!$J$2:$J$95))) | D16: =C16/94
B17: 撕下后留胶 | C17: =SUMPRODUCT(--ISNUMBER(SEARCH("撕下后留胶",'01_打标明细'!$J$2:$J$95))) | D17: =C17/94
A18: 兼容与收纳 | B18: — 小计 | C18: =COUNTIF('01_打标明细'!$I$2:$I$95,"兼容与收纳") | D18: =C18/94
B19: 充电盒收纳 | C19: =SUMPRODUCT(--ISNUMBER(SEARCH("充电盒收纳",'01_打标明细'!$J$2:$J$95))) | D19: =C19/94
B20: 机型适配 | C20: =SUMPRODUCT(--ISNUMBER(SEARCH("机型适配",'01_打标明细'!$J$2:$J$95))) | D20: =C20/94
B21: 兼容宣称兑现度 | C21: =SUMPRODUCT(--ISNUMBER(SEARCH("兼容宣称兑现度",'01_打标明细'!$J$2:$J$95))) | D21: =C21/94
B22: 摄像头视角 | C22: =SUMPRODUCT(--ISNUMBER(SEARCH("摄像头视角",'01_打标明细'!$J$2:$J$95))) | D22: =C22/94
B23: 装上后充电 | C23: =SUMPRODUCT(--ISNUMBER(SEARCH("装上后充电",'01_打标明细'!$J$2:$J$95))) | D23: =C23/94
B24: 充电盒相关(没说清) | C24: =SUMPRODUCT(--ISNUMBER(SEARCH("充电盒相关(没说清)",'01_打标明细'!$J$2:$J$95))) | D24: =C24/94
A25: 材质与做工 | B25: — 小计 | C25: =COUNTIF('01_打标明细'!$I$2:$I$95,"材质与做工") | D25: =C25/94
B26: 整体高度 | C26: =SUMPRODUCT(--ISNUMBER(SEARCH("整体高度",'01_打标明细'!$J$2:$J$95))) | D26: =C26/94
B27: 硅胶软硬 | C27: =SUMPRODUCT(--ISNUMBER(SEARCH("硅胶软硬",'01_打标明细'!$J$2:$J$95))) | D27: =C27/94
B28: 颜色与图片一致 | C28: =SUMPRODUCT(--ISNUMBER(SEARCH("颜色与图片一致",'01_打标明细'!$J$2:$J$95))) | D28: =C28/94
B29: 耐黄变 | C29: =SUMPRODUCT(--ISNUMBER(SEARCH("耐黄变",'01_打标明细'!$J$2:$J$95))) | D29: =C29/94
B30: 边缘做工 | C30: =SUMPRODUCT(--ISNUMBER(SEARCH("边缘做工",'01_打标明细'!$J$2:$J$95))) | D30: =C30/94
A31: 综合质量 | B31: — 小计 | C31: =COUNTIF('01_打标明细'!$I$2:$I$95,"综合质量") | D31: =C31/94
B32: 与预期(泛指) | C32: =SUMPRODUCT(--ISNUMBER(SEARCH("与预期(泛指)",'01_打标明细'!$J$2:$J$95))) | D32: =C32/94
B33: 硅胶软硬 | C33: =SUMPRODUCT(--ISNUMBER(SEARCH("硅胶软硬",'01_打标明细'!$J$2:$J$95))) | D33: =C33/94
B34: 贴片式形态(这一款特有) | C34: =SUMPRODUCT(--ISNUMBER(SEARCH("贴片式形态(这一款特有)",'01_打标明细'!$J$2:$J$95))) | D34: =C34/94
B35: 质量(泛指) | C35: =SUMPRODUCT(--ISNUMBER(SEARCH("质量(泛指)",'01_打标明细'!$J$2:$J$95))) | D35: =C35/94
B36: 值不值 | C36: =SUMPRODUCT(--ISNUMBER(SEARCH("值不值",'01_打标明细'!$J$2:$J$95))) | D36: =C36/94
B37: 同款批次一致性 | C37: =SUMPRODUCT(--ISNUMBER(SEARCH("同款批次一致性",'01_打标明细'!$J$2:$J$95))) | D37: =C37/94
B38: 新旧状态 | C38: =SUMPRODUCT(--ISNUMBER(SEARCH("新旧状态",'01_打标明细'!$J$2:$J$95))) | D38: =C38/94
A39: 非产品因素 | B39: — 小计 | C39: =COUNTIF('01_打标明细'!$I$2:$I$95,"非产品因素") | D39: =C39/94
B40: 发货准确 | C40: =SUMPRODUCT(--ISNUMBER(SEARCH("发货准确",'01_打标明细'!$J$2:$J$95))) | D40: =C40/94
B41: 重复下单 | C41: =SUMPRODUCT(--ISNUMBER(SEARCH("重复下单",'01_打标明细'!$J$2:$J$95))) | D41: =C41/94
...

Sheet 03_该谁改与严重度
A1: 该谁改 —— 每条原话只判一个
A3: 该谁改 | B3: 条数 | C3: 占比 | D3: 哪个部门 | E3: 往哪个方向动
A4: 产品的事 | B4: =COUNTIF('01_打标明细'!$N$2:$N$95,"产品的事") | C4: =B4/$B$10 | D4: 产品 · 研发/品控 | E4: 改结构、改材料、大货抽检
A5: 页面的事 | B5: =COUNTIF('01_打标明细'!$N$2:$N$95,"页面的事") | C5: =B5/$B$10 | D5: 运营 · 页面 | E5: 校准规格表、收敛宣称、补图文
A6: 客户自己选错 | B6: =COUNTIF('01_打标明细'!$N$2:$N$95,"客户自己选错") | C6: =B6/$B$10 | D6: 不算产品问题 | E6: 用来算能挽回多少，优化换档引导
A7: 不该买这款 | B7: =COUNTIF('01_打标明细'!$N$2:$N$95,"不该买这款") | C7: =B7/$B$10 | D7: 品牌 · 定位 | E7: 重新说清楚卖给谁
A8: 说不清 | B8: =COUNTIF('01_打标明细'!$N$2:$N$95,"说不清") | C8: =B8/$B$10 | D8: — | E8: 不拿来做决定，但占比本身是结论
A9: 其他 | B9: =COUNTIF('01_打标明细'!$N$2:$N$95,"其他") | C9: =B9/$B$10 | D9: — | E9: 包装、到货状态等
A10: 合计 | B10: =SUM(B4:B9)
A12: 多严重
A13: 多严重 | B13: 条数 | C13: 占比
A14: 严重 | B14: =COUNTIF('01_打标明细'!$O$2:$O$95,"严重") | C14: =B14/94
A15: 中度 | B15: =COUNTIF('01_打标明细'!$O$2:$O$95,"中度") | C15: =B15/94
A16: 轻度 | B16: =COUNTIF('01_打标明细'!$O$2:$O$95,"轻度") | C16: =B16/94
A19: 能否挽回
A20: 能否挽回 | B20: 条数 | C20: 占比
A21: 是 | B21: =COUNTIF('01_打标明细'!$P$2:$P$95,"是") | C21: =B21/94
A22: 否 | B22: =COUNTIF('01_打标明细'!$P$2:$P$95,"否") | C22: =B22/94
A25: 量小不等于不要紧：每一大类里有几条是「严重」
A26: 大类 | B26: 条数 | C26: 其中严重 | D26: 占全部严重
A27: 高度与贴合 | B27: =COUNTIF('01_打标明细'!$I$2:$I$95,"高度与贴合") | C27: =COUNTIFS('01_打标明细'!$I$2:$I$95,"高度与贴合",'01_打标明细'!$O$2:$O$95,"严重") | D27: =IF(COUNTIF('01_打标明细'!$O$2:$O$95,"严重")=0,0,C27/COUNTIF('01_打标明细'!$O$2:$O$95,"严重"))
A28: 防滑与固定 | B28: =COUNTIF('01_打标明细'!$I$2:$I$95,"防滑与固定") | C28: =COUNTIFS('01_打标明细'!$I$2:$I$95,"防滑与固定",'01_打标明细'!$O$2:$O$95,"严重") | D28: =IF(COUNTIF('01_打标明细'!$O$2:$O$95,"严重")=0,0,C28/COUNTIF('01_打标明细'!$O$2:$O$95,"严重"))
A29: 兼容与收纳 | B29: =COUNTIF('01_打标明细'!$I$2:$I$95,"兼容与收纳") | C29: =COUNTIFS('01_打标明细'!$I$2:$I$95,"兼容与收纳",'01_打标明细'!$O$2:$O$95,"严重") | D29: =IF(COUNTIF('01_打标明细'!$O$2:$O$95,"严重")=0,0,C29/COUNTIF('01_打标明细'!$O$2:$O$95,"严重"))
A30: 佩戴与外观 | B30: =COUNTIF('01_打标明细'!$I$2:$I$95,"佩戴与外观") | C30: =COUNTIFS('01_打标明细'!$I$2:$I$95,"佩戴与外观",'01_打标明细'!$O$2:$O$95,"严重") | D30: =IF(COUNTIF('01_打标明细'!$O$2:$O$95,"严重")=0,0,C30/COUNTIF('01_打标明细'!$O$2:$O$95,"严重"))
A31: 材质与做工 | B31: =COUNTIF('01_打标明细'!$I$2:$I$95,"材质与做工") | C31: =COUNTIFS('01_打标明细'!$I$2:$I$95,"材质与做工",'01_打标明细'!$O$2:$O$95,"严重") | D31: =IF(COUNTIF('01_打标明细'!$O$2:$O$95,"严重")=0,0,C31/COUNTIF('01_打标明细'!$O$2:$O$95,"严重"))
A32: 综合质量 | B32: =COUNTIF('01_打标明细'!$I$2:$I$95,"综合质量") | C32: =COUNTIFS('01_打标明细'!$I$2:$I$95,"综合质量",'01_打标明细'!$O$2:$O$95,"严重") | D32: =IF(COUNTIF('01_打标明细'!$O$2:$O$95,"严重")=0,0,C32/COUNTIF('01_打标明细'!$O$2:$O$95,"严重"))
A33: 非产品因素 | B33: =COUNTIF('01_打标明细'!$I$2:$I$95,"非产品因素") | C33: =COUNTIFS('01_打标明细'!$I$2:$I$95,"非产品因素",'01_打标明细'!$O$2:$O$95,"严重") | D33: =IF(COUNTIF('01_打标明细'!$O$2:$O$95,"严重")=0,0,C33/COUNTIF('01_打标明细'!$O$2:$O$95,"严重"))

Sheet 04_哪件事×规格
A1: 细项 × 规格（数字=条数）｜用来判断：是某个规格的事，还是整条线的事。分组小的格子只看方向
A3: 细项 | B3: 标准款-1.8mm | C3: 标准款-2.5mm | D3: 大号款-1.8mm | E3: 大号款-2.5mm | F3: 合计
A4: 整体高度 | B4: =SUMPRODUCT(--ISNUMBER(SEARCH("整体高度",'01_打标明细'!$J$2:$J$95)),--('01_打标明细'!$E$2:$E$95="标准款-1.8mm")) | C4: =SUMPRODUCT(--ISNUMBER(SEARCH("整体高度",'01_打标明细'!$J$2:$J$95)),--('01_打标明细'!$E$2:$E$95="标准款-2.5mm")) | D4: =SUMPRODUCT(--ISNUMBER(SEARCH("整体高度",'01_打标明细'!$J$2:$J$95)),--('01_打标明细'!$E$2:$E$95="大号款-1.8mm")) | E4: =SUMPRODUCT(--ISNUMBER(SEARCH("整体高度",'01_打标明细'!$J$2:$J$95)),--('01_打标明细'!$E$2:$E$95="大号款-2.5mm")) | F4: =SUM(B4:E4)
A5: 宽度与覆盖 | B5: =SUMPRODUCT(--ISNUMBER(SEARCH("宽度与覆盖",'01_打标明细'!$J$2:$J$95)),--('01_打标明细'!$E$2:$E$95="标准款-1.8mm")) | C5: =SUMPRODUCT(--ISNUMBER(SEARCH("宽度与覆盖",'01_打标明细'!$J$2:$J$95)),--('01_打标明细'!$E$2:$E$95="标准款-2.5mm")) | D5: =SUMPRODUCT(--ISNUMBER(SEARCH("宽度与覆盖",'01_打标明细'!$J$2:$J$95)),--('01_打标明细'!$E$2:$E$95="大号款-1.8mm")) | E5: =SUMPRODUCT(--ISNUMBER(SEARCH("宽度与覆盖",'01_打标明细'!$J$2:$J$95)),--('01_打标明细'!$E$2:$E$95="大号款-2.5mm")) | F5: =SUM(B5:E5)
A6: 与预期(泛指) | B6: =SUMPRODUCT(--ISNUMBER(SEARCH("与预期(泛指)",'01_打标明细'!$J$2:$J$95)),--('01_打标明细'!$E$2:$E$95="标准款-1.8mm")) | C6: =SUMPRODUCT(--ISNUMBER(SEARCH("与预期(泛指)",'01_打标明细'!$J$2:$J$95)),--('01_打标明细'!$E$2:$E$95="标准款-2.5mm")) | D6: =SUMPRODUCT(--ISNUMBER(SEARCH("与预期(泛指)",'01_打标明细'!$J$2:$J$95)),--('01_打标明细'!$E$2:$E$95="大号款-1.8mm")) | E6: =SUMPRODUCT(--ISNUMBER(SEARCH("与预期(泛指)",'01_打标明细'!$J$2:$J$95)),--('01_打标明细'!$E$2:$E$95="大号款-2.5mm")) | F6: =SUM(B6:E6)
A7: 背胶牢固度 | B7: =SUMPRODUCT(--ISNUMBER(SEARCH("背胶牢固度",'01_打标明细'!$J$2:$J$95)),--('01_打标明细'!$E$2:$E$95="标准款-1.8mm")) | C7: =SUMPRODUCT(--ISNUMBER(SEARCH("背胶牢固度",'01_打标明细'!$J$2:$J$95)),--('01_打标明细'!$E$2:$E$95="标准款-2.5mm")) | D7: =SUMPRODUCT(--ISNUMBER(SEARCH("背胶牢固度",'01_打标明细'!$J$2:$J$95)),--('01_打标明细'!$E$2:$E$95="大号款-1.8mm")) | E7: =SUMPRODUCT(--ISNUMBER(SEARCH("背胶牢固度",'01_打标明细'!$J$2:$J$95)),--('01_打标明细'!$E$2:$E$95="大号款-2.5mm")) | F7: =SUM(B7:E7)
A8: 选档指引 | B8: =SUMPRODUCT(--ISNUMBER(SEARCH("选档指引",'01_打标明细'!$J$2:$J$95)),--('01_打标明细'!$E$2:$E$95="标准款-1.8mm")) | C8: =SUMPRODUCT(--ISNUMBER(SEARCH("选档指引",'01_打标明细'!$J$2:$J$95)),--('01_打标明细'!$E$2:$E$95="标准款-2.5mm")) | D8: =SUMPRODUCT(--ISNUMBER(SEARCH("选档指引",'01_打标明细'!$J$2:$J$95)),--('01_打标明细'!$E$2:$E$95="大号款-1.8mm")) | E8: =SUMPRODUCT(--ISNUMBER(SEARCH("选档指引",'01_打标明细'!$J$2:$J$95)),--('01_打标明细'!$E$2:$E$95="大号款-2.5mm")) | F8: =SUM(B8:E8)
A9: 发货准确 | B9: =SUMPRODUCT(--ISNUMBER(SEARCH("发货准确",'01_打标明细'!$J$2:$J$95)),--('01_打标明细'!$E$2:$E$95="标准款-1.8mm")) | C9: =SUMPRODUCT(--ISNUMBER(SEARCH("发货准确",'01_打标明细'!$J$2:$J$95)),--('01_打标明细'!$E$2:$E$95="标准款-2.5mm")) | D9: =SUMPRODUCT(--ISNUMBER(SEARCH("发货准确",'01_打标明细'!$J$2:$J$95)),--('01_打标明细'!$E$2:$E$95="大号款-1.8mm")) | E9: =SUMPRODUCT(--ISNUMBER(SEARCH("发货准确",'01_打标明细'!$J$2:$J$95)),--('01_打标明细'!$E$2:$E$95="大号款-2.5mm")) | F9: =SUM(B9:E9)
A10: 合适度(没说方向) | B10: =SUMPRODUCT(--ISNUMBER(SEARCH("合适度(没说方向)",'01_打标明细'!$J$2:$J$95)),--('01_打标明细'!$E$2:$E$95="标准款-1.8mm")) | C10: =SUMPRODUCT(--ISNUMBER(SEARCH("合适度(没说方向)",'01_打标明细'!$J$2:$J$95)),--('01_打标明细'!$E$2:$E$95="标准款-2.5mm")) | D10: =SUMPRODUCT(--ISNUMBER(SEARCH("合适度(没说方向)",'01_打标明细'!$J$2:$J$95)),--('01_打标明细'!$E$2:$E$95="大号款-1.8mm")) | E10: =SUMPRODUCT(--ISNUMBER(SEARCH("合适度(没说方向)",'01_打标明细'!$J$2:$J$95)),--('01_打标明细'!$E$2:$E$95="大号款-2.5mm")) | F10: =SUM(B10:E10)
A11: 防滑效果(泛指) | B11: =SUMPRODUCT(--ISNUMBER(SEARCH("防滑效果(泛指)",'01_打标明细'!$J$2:$J$95)),--('01_打标明细'!$E$2:$E$95="标准款-1.8mm")) | C11: =SUMPRODUCT(--ISNUMBER(SEARCH("防滑效果(泛指)",'01_打标明细'!$J$2:$J$95)),--('01_打标明细'!$E$2:$E$95="标准款-2.5mm")) | D11: =SUMPRODUCT(--ISNUMBER(SEARCH("防滑效果(泛指)",'01_打标明细'!$J$2:$J$95)),--('01_打标明细'!$E$2:$E$95="大号款-1.8mm")) | E11: =SUMPRODUCT(--ISNUMBER(SEARCH("防滑效果(泛指)",'01_打标明细'!$J$2:$J$95)),--('01_打标明细'!$E$2:$E$95="大号款-2.5mm")) | F11: =SUM(B11:E11)
A12: 充电盒收纳 | B12: =SUMPRODUCT(--ISNUMBER(SEARCH("充电盒收纳",'01_打标明细'!$J$2:$J$95)),--('01_打标明细'!$E$2:$E$95="标准款-1.8mm")) | C12: =SUMPRODUCT(--ISNUMBER(SEARCH("充电盒收纳",'01_打标明细'!$J$2:$J$95)),--('01_打标明细'!$E$2:$E$95="标准款-2.5mm")) | D12: =SUMPRODUCT(--ISNUMBER(SEARCH("充电盒收纳",'01_打标明细'!$J$2:$J$95)),--('01_打标明细'!$E$2:$E$95="大号款-1.8mm")) | E12: =SUMPRODUCT(--ISNUMBER(SEARCH("充电盒收纳",'01_打标明细'!$J$2:$J$95)),--('01_打标明细'!$E$2:$E$95="大号款-2.5mm")) | F12: =SUM(B12:E12)
A13: 机型适配 | B13: =SUMPRODUCT(--ISNUMBER(SEARCH("机型适配",'01_打标明细'!$J$2:$J$95)),--('01_打标明细'!$E$2:$E$95="标准款-1.8mm")) | C13: =SUMPRODUCT(--ISNUMBER(SEARCH("机型适配",'01_打标明细'!$J$2:$J$95)),--('01_打标明细'!$E$2:$E$95="标准款-2.5mm")) | D13: =SUMPRODUCT(--ISNUMBER(SEARCH("机型适配",'01_打标明细'!$J$2:$J$95)),--('01_打标明细'!$E$2:$E$95="大号款-1.8mm")) | E13: =SUMPRODUCT(--ISNUMBER(SEARCH("机型适配",'01_打标明细'!$J$2:$J$95)),--('01_打标明细'!$E$2:$E$95="大号款-2.5mm")) | F13: =SUM(B13:E13)
A14: 硅胶软硬 | B14: =SUMPRODUCT(--ISNUMBER(SEARCH("硅胶软硬",'01_打标明细'!$J$2:$J$95)),--('01_打标明细'!$E$2:$E$95="标准款-1.8mm")) | C14: =SUMPRODUCT(--ISNUMBER(SEARCH("硅胶软硬",'01_打标明细'!$J$2:$J$95)),--('01_打标明细'!$E$2:$E$95="标准款-2.5mm")) | D14: =SUMPRODUCT(--ISNUMBER(SEARCH("硅胶软硬",'01_打标明细'!$J$2:$J$95)),--('01_打标明细'!$E$2:$E$95="大号款-1.8mm")) | E14: =SUMPRODUCT(--ISNUMBER(SEARCH("硅胶软硬",'01_打标明细'!$J$2:$J$95)),--('01_打标明细'!$E$2:$E$95="大号款-2.5mm")) | F14: =SUM(B14:E14)
A15: 兼容宣称兑现度 | B15: =SUMPRODUCT(--ISNUMBER(SEARCH("兼容宣称兑现度",'01_打标明细'!$J$2:$J$95)),--('01_打标明细'!$E$2:$E$95="标准款-1.8mm")) | C15: =SUMPRODUCT(--ISNUMBER(SEARCH("兼容宣称兑现度",'01_打标明细'!$J$2:$J$95)),--('01_打标明细'!$E$2:$E$95="标准款-2.5mm")) | D15: =SUMPRODUCT(--ISNUMBER(SEARCH("兼容宣称兑现度",'01_打标明细'!$J$2:$J$95)),--('01_打标明细'!$E$2:$E$95="大号款-1.8mm")) | E15: =SUMPRODUCT(--ISNUMBER(SEARCH("兼容宣称兑现度",'01_打标明细'!$J$2:$J$95)),--('01_打标明细'!$E$2:$E$95="大号款-2.5mm")) | F15: =SUM(B15:E15)
A16: 摄像头视角 | B16: =SUMPRODUCT(--ISNUMBER(SEARCH("摄像头视角",'01_打标明细'!$J$2:$J$95)),--('01_打标明细'!$E$2:$E$95="标准款-1.8mm")) | C16: =SUMPRODUCT(--ISNUMBER(SEARCH("摄像头视角",'01_打标明细'!$J$2:$J$95)),--('01_打标明细'!$E$2:$E$95="标准款-2.5mm")) | D16: =SUMPRODUCT(--ISNUMBER(SEARCH("摄像头视角",'01_打标明细'!$J$2:$J$95)),--('01_打标明细'!$E$2:$E$95="大号款-1.8mm")) | E16: =SUMPRODUCT(--ISNUMBER(SEARCH("摄像头视角",'01_打标明细'!$J$2:$J$95)),--('01_打标明细'!$E$2:$E$95="大号款-2.5mm")) | F16: =SUM(B16:E16)
A17: 贴片式形态(这一款特有) | B17: =SUMPRODUCT(--ISNUMBER(SEARCH("贴片式形态(这一款特有)",'01_打标明细'!$J$2:$J$95)),--('01_打标明细'!$E$2:$E$95="标准款-1.8mm")) | C17: =SUMPRODUCT(--ISNUMBER(SEARCH("贴片式形态(这一款特有)",'01_打标明细'!$J$2:$J$95)),--('01_打标明细'!$E$2:$E$95="标准款-2.5mm")) | D17: =SUMPRODUCT(--ISNUMBER(SEARCH("贴片式形态(这一款特有)",'01_打标明细'!$J$2:$J$95)),--('01_打标明细'!$E$2:$E$95="大号款-1.8mm")) | E17: =SUMPRODUCT(--ISNUMBER(SEARCH("贴片式形态(这一款特有)",'01_打标明细'!$J$2:$J$95)),--('01_打标明细'!$E$2:$E$95="大号款-2.5mm")) | F17: =SUM(B17:E17)
A18: 装上后充电 | B18: =SUMPRODUCT(--ISNUMBER(SEARCH("装上后充电",'01_打标明细'!$J$2:$J$95)),--('01_打标明细'!$E$2:$E$95="标准款-1.8mm")) | C18: =SUMPRODUCT(--ISNUMBER(SEARCH("装上后充电",'01_打标明细'!$J$2:$J$95)),--('01_打标明细'!$E$2:$E$95="标准款-2.5mm")) | D18: =SUMPRODUCT(--ISNUMBER(SEARCH("装上后充电",'01_打标明细'!$J$2:$J$95)),--('01_打标明细'!$E$2:$E$95="大号款-1.8mm")) | E18: =SUMPRODUCT(--ISNUMBER(SEARCH("装上后充电",'01_打标明细'!$J$2:$J$95)),--('01_打标明细'!$E$2:$E$95="大号款-2.5mm")) | F18: =SUM(B18:E18)
A19: 防滑宣称兑现度 | B19: =SUMPRODUCT(--ISNUMBER(SEARCH("防滑宣称兑现度",'01_打标明细'!$J$2:$J$95)),--('01_打标明细'!$E$2:$E$95="标准款-1.8mm")) | C19: =SUMPRODUCT(--ISNUMBER(SEARCH("防滑宣称兑现度",'01_打标明细'!$J$2:$J$95)),--('01_打标明细'!$E$2:$E$95="标准款-2.5mm")) | D19: =SUMPRODUCT(--ISNUMBER(SEARCH("防滑宣称兑现度",'01_打标明细'!$J$2:$J$95)),--('01_打标明细'!$E$2:$E$95="大号款-1.8mm")) | E19: =SUMPRODUCT(--ISNUMBER(SEARCH("防滑宣称兑现度",'01_打标明细'!$J$2:$J$95)),--('01_打标明细'!$E$2:$E$95="大号款-2.5mm")) | F19: =SUM(B19:E19)
A20: 质量(泛指) | B20: =SUMPRODUCT(--ISNUMBER(SEARCH("质量(泛指)",'01_打标明细'!$J$2:$J$95)),--('01_打标明细'!$E$2:$E$95="标准款-1.8mm")) | C20: =SUMPRODUCT(--ISNUMBER(SEARCH("质量(泛指)",'01_打标明细'!$J$2:$J$95)),--('01_打标明细'!$E$2:$E$95="标准款-2.5mm")) | D20: =SUMPRODUCT(--ISNUMBER(SEARCH("质量(泛指)",'01_打标明细'!$J$2:$J$95)),--('01_打标明细'!$E$2:$E$95="大号款-1.8mm")) | E20: =SUMPRODUCT(--ISNUMBER(SEARCH("质量(泛指)",'01_打标明细'!$J$2:$J$95)),--('01_打标明细'!$E$2:$E$95="大号款-2.5mm")) | F20: =SUM(B20:E20)
A21: 颜色与图片一致 | B21: =SUMPRODUCT(--ISNUMBER(SEARCH("颜色与图片一致",'01_打标明细'!$J$2:$J$95)),--('01_打标明细'!$E$2:$E$95="标准款-1.8mm")) | C21: =SUMPRODUCT(--ISNUMBER(SEARCH("颜色与图片一致",'01_打标明细'!$J$2:$J$95)),--('01_打标明细'!$E$2:$E$95="标准款-2.5mm")) | D21: =SUMPRODUCT(--ISNUMBER(SEARCH("颜色与图片一致",'01_打标明细'!$J$2:$J$95)),--('01_打标明细'!$E$2:$E$95="大号款-1.8mm")) | E21: =SUMPRODUCT(--ISNUMBER(SEARCH("颜色与图片一致",'01_打标明细'!$J$2:$J$95)),--('01_打标明细'!$E$2:$E$95="大号款-2.5mm")) | F21: =SUM(B21:E21)
A22: 出汗时防滑 | B22: =SUMPRODUCT(--ISNUMBER(SEARCH("出汗时防滑",'01_打标明细'!$J$2:$J$95)),--('01_打标明细'!$E$2:$E$95="标准款-1.8mm")) | C22: =SUMPRODUCT(--ISNUMBER(SEARCH("出汗时防滑",'01_打标明细'!$J$2:$J$95)),--('01_打标明细'!$E$2:$E$95="标准款-2.5mm")) | D22: =SUMPRODUCT(--ISNUMBER(SEARCH("出汗时防滑",'01_打标明细'!$J$2:$J$95)),--('01_打标明细'!$E$2:$E$95="大号款-1.8mm")) | E22: =SUMPRODUCT(--ISNUMBER(SEARCH("出汗时防滑",'01_打标明细'!$J$2:$J$95)),--('01_打标明细'!$E$2:$E$95="大号款-2.5mm")) | F22: =SUM(B22:E22)
A23: 耐黄变 | B23: =SUMPRODUCT(--ISNUMBER(SEARCH("耐黄变",'01_打标明细'!$J$2:$J$95)),--('01_打标明细'!$E$2:$E$95="标准款-1.8mm")) | C23: =SUMPRODUCT(--ISNUMBER(SEARCH("耐黄变",'01_打标明细'!$J$2:$J$95)),--('01_打标明细'!$E$2:$E$95="标准款-2.5mm")) | D23: =SUMPRODUCT(--ISNUMBER(SEARCH("耐黄变",'01_打标明细'!$J$2:$J$95)),--('01_打标明细'!$E$2:$E$95="大号款-1.8mm")) | E23: =SUMPRODUCT(--ISNUMBER(SEARCH("耐黄变",'01_打标明细'!$J$2:$J$95)),--('01_打标明细'!$E$2:$E$95="大号款-2.5mm")) | F23: =SUM(B23:E23)
A24: 值不值 | B24: =SUMPRODUCT(--ISNUMBER(SEARCH("值不值",'01_打标明细'!$J$2:$J$95)),--('01_打标明细'!$E$2:$E$95="标准款-1.8mm")) | C24: =SUMPRODUCT(--ISNUMBER(SEARCH("值不值",'01_打标明细'!$J$2:$J$95)),--('01_打标明细'!$E$2:$E$95="标准款-2.5mm")) | D24: =SUMPRODUCT(--ISNUMBER(SEARCH("值不值",'01_打标明细'!$J$2:$J$95)),--('01_打标明细'!$E$2:$E$95="大号款-1.8mm")) | E24: =SUMPRODUCT(--ISNUMBER(SEARCH("值不值",'01_打标明细'!$J$2:$J$95)),--('01_打标明细'!$E$2:$E$95="大号款-2.5mm")) | F24: =SUM(B24:E24)
A25: 撕下后留胶 | B25: =SUMPRODUCT(--ISNUMBER(SEARCH("撕下后留胶",'01_打标明细'!$J$2:$J$95)),--('01_打标明细'!$E$2:$E$95="标准款-1.8mm")) | C25: =SUMPRODUCT(--ISNUMBER(SEARCH("撕下后留胶",'01_打标明细'!$J$2:$J$95)),--('01_打标明细'!$E$2:$E$95="标准款-2.5mm")) | D25: =SUMPRODUCT(--ISNUMBER(SEARCH("撕下后留胶",'01_打标明细'!$J$2:$J$95)),--('01_打标明细'!$E$2:$E$95="大号款-1.8mm")) | E25: =SUMPRODUCT(--ISNUMBER(SEARCH("撕下后留胶",'01_打标明细'!$J$2:$J$95)),--('01_打标明细'!$E$2:$E$95="大号款-2.5mm")) | F25: =SUM(B25:E25)
A26: 边缘做工 | B26: =SUMPRODUCT(--ISNUMBER(SEARCH("边缘做工",'01_打标明细'!$J$2:$J$95)),--('01_打标明细'!$E$2:$E$95="标准款-1.8mm")) | C26: =SUMPRODUCT(--ISNUMBER(SEARCH("边缘做工",'01_打标明细'!$J$2:$J$95)),--('01_打标明细'!$E$2:$E$95="标准款-2.5mm")) | D26: =SUMPRODUCT(--ISNUMBER(SEARCH("边缘做工",'01_打标明细'!$J$2:$J$95)),--('01_打标明细'!$E$2:$E$95="大号款-1.8mm")) | E26: =SUMPRODUCT(--ISNUMBER(SEARCH("边缘做工",'01_打标明细'!$J$2:$J$95)),--('01_打标明细'!$E$2:$E$95="大号款-2.5mm")) | F26: =SUM(B26:E26)
A27: 同款批次一致性 | B27: =SUMPRODUCT(--ISNUMBER(SEARCH("同款批次一致性",'01_打标明细'!$J$2:$J$95)),--('01_打标明细'!$E$2:$E$95="标准款-1.8mm")) | C27: =SUMPRODUCT(--ISNUMBER(SEARCH("同款批次一致性",'01_打标明细'!$J$2:$J$95)),--('01_打标明细'!$E$2:$E$95="标准款-2.5mm")) | D27: =SUMPRODUCT(--ISNUMBER(SEARCH("同款批次一致性",'01_打标明细'!$J$2:$J$95)),--('01_打标明细'!$E$2:$E$95="大号款-1.8mm")) | E27: =SUMPRODUCT(--ISNUMBER(SEARCH("同款批次一致性",'01_打标明细'!$J$2:$J$95)),--('01_打标明细'!$E$2:$E$95="大号款-2.5mm")) | F27: =SUM(B27:E27)
A28: 重复下单 | B28: =SUMPRODUCT(--ISNUMBER(SEARCH("重复下单",'01_打标明细'!$J$2:$J$95)),--('01_打标明细'!$E$2:$E$95="标准款-1.8mm")) | C28: =SUMPRODUCT(--ISNUMBER(SEARCH("重复下单",'01_打标明细'!$J$2:$J$95)),--('01_打标明细'!$E$2:$E$95="标准款-2.5mm")) | D28: =SUMPRODUCT(--ISNUMBER(SEARCH("重复下单",'01_打标明细'!$J$2:$J$95)),--('01_打标明细'!$E$2:$E$95="大号款-1.8mm")) | E28: =SUMPRODUCT(--ISNUMBER(SEARCH("重复下单",'01_打标明细'!$J$2:$J$95)),--('01_打标明细'!$E$2:$E$95="大号款-2.5mm")) | F28: =SUM(B28:E28)
A29: 充电盒相关(没说清) | B29: =SUMPRODUCT(--ISNUMBER(SEARCH("充电盒相关(没说清)",'01_打标明细'!$J$2:$J$95)),--('01_打标明细'!$E$2:$E$95="标准款-1.8mm")) | C29: =SUMPRODUCT(--ISNUMBER(SEARCH("充电盒相关(没说清)",'01_打标明细'!$J$2:$J$95)),--('01_打标明细'!$E$2:$E$95="标准款-2.5mm")) | D29: =SUMPRODUCT(--ISNUMBER(SEARCH("充电盒相关(没说清)",'01_打标明细'!$J$2:$J$95)),--('01_打标明细'!$E$2:$E$95="大号款-1.8mm")) | E29: =SUMPRODUCT(--ISNUMBER(SEARCH("充电盒相关(没说清)",'01_打标明细'!$J$2:$J$95)),--('01_打标明细'!$E$2:$E$95="大号款-2.5mm")) | F29: =SUM(B29:E29)
A30: 新旧状态 | B30: =SUMPRODUCT(--ISNUMBER(SEARCH("新旧状态",'01_打标明细'!$J$2:$J$95)),--('01_打标明细'!$E$2:$E$95="标准款-1.8mm")) | C30: =SUMPRODUCT(--ISNUMBER(SEARCH("新旧状态",'01_打标明细'!$J$2:$J$95)),--('01_打标明细'!$E$2:$E$95="标准款-2.5mm")) | D30: =SUMPRODUCT(--ISNUMBER(SEARCH("新旧状态",'01_打标明细'!$J$2:$J$95)),--('01_打标明细'!$E$2:$E$95="大号款-1.8mm")) | E30: =SUMPRODUCT(--ISNUMBER(SEARCH("新旧状态",'01_打标明细'!$J$2:$J$95)),--('01_打标明细'!$E$2:$E$95="大号款-2.5mm")) | F30: =SUM(B30:E30)
A31: 这个规格的原话总数（大盘） | B31: =COUNTIF('01_打标明细'!$E$2:$E$95,"标准款-1.8mm") | C31: =COUNTIF('01_打标明细'!$E$2:$E$95,"标准款-2.5mm") | D31: =COUNTIF('01_打标明细'!$E$2:$E$95,"大号款-1.8mm") | E31: =COUNTIF('01_打标明细'!$E$2:$E$95,"大号款-2.5mm")

Sheet 05_该谁改×原因码
A1: 该谁改 × 平台原因码（看平台记的原因，和读出来的真实原因差多远）
A3: 该谁改 | B3: 与描述不符 NOT_AS_DESCRIBED | C3: 有缺陷 DEFECTIVE | D3: 质量不满意 QUALITY_UNACCEPTABLE | E3: 不兼容 NOT_COMPATIBLE | F3: 买家选错商品 ORDERED_WRONG_ITEM | G3: 下错单 MISORDERED | H3: 合计
A4: 产品的事 | B4: =SUMPRODUCT(--('01_打标明细'!$N$2:$N$95="产品的事"),--('01_打标明细'!$G$2:$G$95="NOT_AS_DESCRIBED")) | C4: =SUMPRODUCT(--('01_打标明细'!$N$2:$N$95="产品的事"),--('01_打标明细'!$G$2:$G$95="DEFECTIVE")) | D4: =SUMPRODUCT(--('01_打标明细'!$N$2:$N$95="产品的事"),--('01_打标明细'!$G$2:$G$95="QUALITY_UNACCEPTABLE")) | E4: =SUMPRODUCT(--('01_打标明细'!$N$2:$N$95="产品的事"),--('01_打标明细'!$G$2:$G$95="NOT_COMPATIBLE")) | F4: =SUMPRODUCT(--('01_打标明细'!$N$2:$N$95="产品的事"),--('01_打标明细'!$G$2:$G$95="ORDERED_WRONG_ITEM")) | G4: =SUMPRODUCT(--('01_打标明细'!$N$2:$N$95="产品的事"),--('01_打标明细'!$G$2:$G$95="MISORDERED")) | H4: =SUM(B4:G4)
A5: 页面的事 | B5: =SUMPRODUCT(--('01_打标明细'!$N$2:$N$95="页面的事"),--('01_打标明细'!$G$2:$G$95="NOT_AS_DESCRIBED")) | C5: =SUMPRODUCT(--('01_打标明细'!$N$2:$N$95="页面的事"),--('01_打标明细'!$G$2:$G$95="DEFECTIVE")) | D5: =SUMPRODUCT(--('01_打标明细'!$N$2:$N$95="页面的事"),--('01_打标明细'!$G$2:$G$95="QUALITY_UNACCEPTABLE")) | E5: =SUMPRODUCT(--('01_打标明细'!$N$2:$N$95="页面的事"),--('01_打标明细'!$G$2:$G$95="NOT_COMPATIBLE")) | F5: =SUMPRODUCT(--('01_打标明细'!$N$2:$N$95="页面的事"),--('01_打标明细'!$G$2:$G$95="ORDERED_WRONG_ITEM")) | G5: =SUMPRODUCT(--('01_打标明细'!$N$2:$N$95="页面的事"),--('01_打标明细'!$G$2:$G$95="MISORDERED")) | H5: =SUM(B5:G5)
A6: 客户自己选错 | B6: =SUMPRODUCT(--('01_打标明细'!$N$2:$N$95="客户自己选错"),--('01_打标明细'!$G$2:$G$95="NOT_AS_DESCRIBED")) | C6: =SUMPRODUCT(--('01_打标明细'!$N$2:$N$95="客户自己选错"),--('01_打标明细'!$G$2:$G$95="DEFECTIVE")) | D6: =SUMPRODUCT(--('01_打标明细'!$N$2:$N$95="客户自己选错"),--('01_打标明细'!$G$2:$G$95="QUALITY_UNACCEPTABLE")) | E6: =SUMPRODUCT(--('01_打标明细'!$N$2:$N$95="客户自己选错"),--('01_打标明细'!$G$2:$G$95="NOT_COMPATIBLE")) | F6: =SUMPRODUCT(--('01_打标明细'!$N$2:$N$95="客户自己选错"),--('01_打标明细'!$G$2:$G$95="ORDERED_WRONG_ITEM")) | G6: =SUMPRODUCT(--('01_打标明细'!$N$2:$N$95="客户自己选错"),--('01_打标明细'!$G$2:$G$95="MISORDERED")) | H6: =SUM(B6:G6)
A7: 不该买这款 | B7: =SUMPRODUCT(--('01_打标明细'!$N$2:$N$95="不该买这款"),--('01_打标明细'!$G$2:$G$95="NOT_AS_DESCRIBED")) | C7: =SUMPRODUCT(--('01_打标明细'!$N$2:$N$95="不该买这款"),--('01_打标明细'!$G$2:$G$95="DEFECTIVE")) | D7: =SUMPRODUCT(--('01_打标明细'!$N$2:$N$95="不该买这款"),--('01_打标明细'!$G$2:$G$95="QUALITY_UNACCEPTABLE")) | E7: =SUMPRODUCT(--('01_打标明细'!$N$2:$N$95="不该买这款"),--('01_打标明细'!$G$2:$G$95="NOT_COMPATIBLE")) | F7: =SUMPRODUCT(--('01_打标明细'!$N$2:$N$95="不该买这款"),--('01_打标明细'!$G$2:$G$95="ORDERED_WRONG_ITEM")) | G7: =SUMPRODUCT(--('01_打标明细'!$N$2:$N$95="不该买这款"),--('01_打标明细'!$G$2:$G$95="MISORDERED")) | H7: =SUM(B7:G7)
A8: 说不清 | B8: =SUMPRODUCT(--('01_打标明细'!$N$2:$N$95="说不清"),--('01_打标明细'!$G$2:$G$95="NOT_AS_DESCRIBED")) | C8: =SUMPRODUCT(--('01_打标明细'!$N$2:$N$95="说不清"),--('01_打标明细'!$G$2:$G$95="DEFECTIVE")) | D8: =SUMPRODUCT(--('01_打标明细'!$N$2:$N$95="说不清"),--('01_打标明细'!$G$2:$G$95="QUALITY_UNACCEPTABLE")) | E8: =SUMPRODUCT(--('01_打标明细'!$N$2:$N$95="说不清"),--('01_打标明细'!$G$2:$G$95="NOT_COMPATIBLE")) | F8: =SUMPRODUCT(--('01_打标明细'!$N$2:$N$95="说不清"),--('01_打标明细'!$G$2:$G$95="ORDERED_WRONG_ITEM")) | G8: =SUMPRODUCT(--('01_打标明细'!$N$2:$N$95="说不清"),--('01_打标明细'!$G$2:$G$95="MISORDERED")) | H8: =SUM(B8:G8)
A9: 其他 | B9: =SUMPRODUCT(--('01_打标明细'!$N$2:$N$95="其他"),--('01_打标明细'!$G$2:$G$95="NOT_AS_DESCRIBED")) | C9: =SUMPRODUCT(--('01_打标明细'!$N$2:$N$95="其他"),--('01_打标明细'!$G$2:$G$95="DEFECTIVE")) | D9: =SUMPRODUCT(--('01_打标明细'!$N$2:$N$95="其他"),--('01_打标明细'!$G$2:$G$95="QUALITY_UNACCEPTABLE")) | E9: =SUMPRODUCT(--('01_打标明细'!$N$2:$N$95="其他"),--('01_打标明细'!$G$2:$G$95="NOT_COMPATIBLE")) | F9: =SUMPRODUCT(--('01_打标明细'!$N$2:$N$95="其他"),--('01_打标明细'!$G$2:$G$95="ORDERED_WRONG_ITEM")) | G9: =SUMPRODUCT(--('01_打标明细'!$N$2:$N$95="其他"),--('01_打标明细'!$G$2:$G$95="MISORDERED")) | H9: =SUM(B9:G9)
A10: 合计 | B10: =COUNTIF('01_打标明细'!$G$2:$G$95,"NOT_AS_DESCRIBED") | C10: =COUNTIF('01_打标明细'!$G$2:$G$95,"DEFECTIVE") | D10: =COUNTIF('01_打标明细'!$G$2:$G$95,"QUALITY_UNACCEPTABLE") | E10: =COUNTIF('01_打标明细'!$G$2:$G$95,"NOT_COMPATIBLE") | F10: =COUNTIF('01_打标明细'!$G$2:$G$95,"ORDERED_WRONG_ITEM") | G10: =COUNTIF('01_打标明细'!$G$2:$G$95,"MISORDERED") | H10: =SUM(B10:G10)

Sheet 06_大盘与两头对称
A1: 平台原因码的大盘（客户在下拉框里随手选的，只作参考，不拿来判该谁改）
A3: 原因码 | B3: 中文 | C3: 条数 | D3: 占本次范围 | E3: 处理
A4: NOT_AS_DESCRIBED | B4: 与描述不符 | C4: 89 | D4: 0.2493 | E4: 留
A5: NOT_COMPATIBLE | B5: 不兼容 | C5: 64 | D5: 0.1793 | E5: 留
A6: DEFECTIVE | B6: 有缺陷 | C6: 61 | D6: 0.1709 | E6: 留
A7: QUALITY_UNACCEPTABLE | B7: 质量不满意 | C7: 38 | D7: 0.1064 | E7: 留
A8: UNWANTED_ITEM | B8: 不再需要 | C8: 29 | D8: 0.0812 | E8: 剔
A9: ORDERED_WRONG_ITEM | B9: 买家选错商品 | C9: 22 | D9: 0.0616 | E9: 留
A10: NO_REASON_GIVEN | B10: 未提供原因 | C10: 15 | D10: 0.042 | E10: 剔
A11: MISORDERED | B11: 下错单 | C11: 9 | D11: 0.0252 | E11: 留
A12: FOUND_BETTER_PRICE | B12: 找到更便宜的 | C12: 7 | D12: 0.0196 | E12: 剔
A13: DAMAGED_BY_FC | B13: 运营中心损坏 | C13: 7 | D13: 0.0196 | E13: 剔
A14: UNAUTHORIZED_PURCHASE | B14: 未经授权购买 | C14: 4 | D14: 0.0112 | E14: 剔
A15: UNDELIVERABLE_UNKNOWN | B15: 无法投递 | C15: 4 | D15: 0.0112 | E15: 剔
... A19: MISSING_PARTS | B19: 缺少部件 | C19: 2 | D19: 0.0056 | E19: 剔
A22: 两头是否对称（整体一层，再到每一项）
A23: 哪一层 / 哪一项 | B23: 一头 | C23: 条数 | D23: 另一头 | E23: 条数 | F23: 差距(点) | G23: 判定
A24: 整体高度·原话层 | B24: 偏高 | C24: 15 | D24: 偏矮 | E24: 16 | F24: 3.2 | G24: 正常
A25: 逐项·宽度与覆盖 | B25: 偏宽 | C25: 9 | D25: 偏窄 | E25: 0 | F25: 100 | G25: 一边倒
A26: 逐项·硅胶软硬 | B26: 偏硬 | C26: 3 | D26: 偏软 | E26: 1 | F26: 50 | G26: 样本少
