Workbook

Sheet 打标明细
A1: 序号 | B1: 记录编号 | C1: 星级 | D1: 站点 | E1: 品名 | F1: 产品 | G1: 规格 | H1: 适配机型 | I1: 高度档 | J1: 日期 | K1: 月份 | L1: 疑似不可信 | M1: 疑似原因 | N1: 原话 | O1: 谁在说 | P1: 什么情况下 | Q1: 好评的事 | R1: 差评的事 | S1: 落差指向 | T1: 过程感受 | U1: 再问一层 | V1: 该谁改 | W1: 多严重 | X1: 整体好坏
A2: 1 | B2: SAMPLE-RV-0001 | C2: 5 | D2: US | E2: 智能眼镜 硅胶防滑鼻托 背胶款 2对装 | F2: A款-防滑鼻托套装(2对装) | G2: 标准款-1.8mm | H2: 标准款 | I2: 1.8mm | J2: 2026-01-04 | K2: 2026-01 | L2: 否 | N2: My glasses used to slide down every time I looked at my phone. With these on they stay put all day. Super comfortable too, I forget they are there. | P2: 全天佩戴 | Q2: 防滑效果(泛指); 佩戴舒适 | U2: 防滑效果(泛指)>什么场合=低头 | X2: 好评
A3: 2 | B3: SAMPLE-RV-0002 | C3: 5 | D3: US | E3: 智能眼镜 硅胶防滑鼻托 背胶款 2对装 | F3: A款-防滑鼻托套装(2对装) | G3: 标准款-2.5mm | H3: 标准款 | I3: 2.5mm | J3: 2026-01-06 | K3: 2026-01 | L3: 否 | N3: Low nose bridge here. The 2.5 lifts the frames off my cheeks finally. Easy to put on, took two minutes. | Q3: 整体高度; 安装难易 | X3: 好评
A4: 3 | B4: SAMPLE-RV-0003 | C4: 4 | D4: US | E4: 智能眼镜 硅胶防滑鼻托 背胶款 2对装 | F4: A款-防滑鼻托套装(2对装) | G4: 标准款-1.8mm | H4: 标准款 | I4: 1.8mm | J4: 2026-01-07 | K4: 2026-01 | L4: 否 | N4: Works well for stopping the slide. Only complaint is they are a bit wider than the original pads so you can see the edge if you look closely. | O4: 原装鼻托 | Q4: 防滑效果(泛指) | R4: 宽度与覆盖:偏宽; 外观隐形 | V4: 产品的事 | W4: 轻度 | X4: 好评
A5: 4 | B5: SAMPLE-RV-0004 | C5: 5 | D5: US | E5: 智能眼镜 硅胶防滑鼻托 背胶款 2对装 | F5: A款-防滑鼻托套装(2对装) | G5: 大号款-1.8mm | H5: 大号款 | I5: 1.8mm | J5: 2026-01-09 | K5: 2026-01 | L5: 否 | N5: Perfect. No more pushing my glasses up every five minutes. Still fits in the charging case with the 1.8. | P5: 放回充电盒时 | Q5: 防滑效果(泛指); 充电盒收纳 | X5: 好评
A6: 5 | B6: SAMPLE-RV-0005 | C6: 5 | D6: US | E6: 智能眼镜 硅胶防滑鼻托 背胶款 2对装 | F6: A款-防滑鼻托套装(2对装) | G6: 标准款-1.8mm | H6: 标准款 | I6: 1.8mm | J6: 2026-01-11 | K6: 2026-01 | L6: 否 | N6: I was using folded tissue under the nose pads before, this is so much better. Soft and comfy. | O6: 自己垫东西 | Q6: 佩戴舒适; 硅胶软硬 | X6: 好评
A7: 6 | B7: SAMPLE-RV-0006 | C7: 3 | D7: US | E7: 智能眼镜 硅胶防滑鼻托 背胶款 2对装 | F7: A款-防滑鼻托套装(2对装) | G7: 标准款-2.5mm | H7: 标准款 | I7: 2.5mm | J7: 2026-01-12 | K7: 2026-01 | L7: 否 | N7: Comfortable and they do stop the slipping, but with the 2.5 my glasses no longer fit in the charging case. Wish the listing had said so. | P7: 放回充电盒时 | Q7: 佩戴舒适; 防滑效果(泛指) | R7: 充电盒收纳 | S7: 充电盒收纳 | U7: 充电盒收纳>怎么个不行=放不进去或合不上盖 | V7: 页面的事 | W7: 中度 | X7: 中性
A8: 7 | B8: SAMPLE-RV-0007 | C8: 5 | D8: US | E8: 智能眼镜 硅胶防滑鼻托 背胶款 2对装 | F8: A款-防滑鼻托套装(2对装) | G8: 大号款-1.8mm | H8: 大号款 | I8: 1.8mm | J8: 2026-01-15 | K8: 2026-01 | L8: 否 | N8: Bought these for my husband, he wears his glasses all day and says they are way more comfortable now. He stopped complaining about them sliding. | O8: 代买(伴侣) | P8: 全天佩戴 | Q8: 佩戴舒适; 防滑效果(泛指) | X8: 好评
A9: 8 | B9: SAMPLE-RV-0008 | C9: 4 | D9: US | E9: 智能眼镜 硅胶防滑鼻托 背胶款 2对装 | F9: A款-防滑鼻托套装(2对装) | G9: 标准款-2.5mm | H9: 标准款 | I9: 2.5mm | J9: 2026-01-17 | K9: 2026-01 | L9: 否 | N9: Good grip, stays on even at the gym. A little tall for my taste but I got used to it. | P9: 运动出汗 | Q9: 防滑效果(泛指); 出汗时防滑 | R9: 整体高度:偏高 | U9: 防滑效果(泛指)>什么场合=运动 | V9: 说不清 | W9: 轻度 | X9: 好评
A10: 9 | B10: SAMPLE-RV-0009 | C10: 5 | D10: US | E10: 智能眼镜 硅胶防滑鼻托 背胶款 2对装 | F10: A款-防滑鼻托套装(2对装) | G10: 标准款-1.8mm | H10: 标准款 | I10: 1.8mm | J10: 2026-01-19 | K10: 2026-01 | L10: 否 | N10: Tried another brand before and those fell off in a week. These have been on for a month, still solid. | O10: 其他品牌鼻托 | Q10: 背胶牢固度 | T10: 戴稳踏实感(夸) | X10: 好评
A11: 10 | B11: SAMPLE-RV-0010 | C11: 2 | D11: US | E11: 智能眼镜 硅胶防滑鼻托 背胶款 2对装 | F11: A款-防滑鼻托套装(2对装) | G11: 标准款-2.5mm | H11: 标准款 | I11: 2.5mm | J11: 2026-01-21 | K11: 2026-01 | L11: 否 | N11: They stop the sliding but the camera now points up, all my videos are aimed at the sky. Also does not fit the case. | Q11: 防滑效果(泛指) | R11: 摄像头视角; 充电盒收纳 | U11: 充电盒收纳>怎么个不行=放不进去或合不上盖 | V11: 产品的事 | W11: 中度 | X11: 差评
A12: 11 | B12: SAMPLE-RV-0011 | C12: 5 | D12: US | E12: 智能眼镜 硅胶防滑鼻托 背胶款 2对装 | F12: A款-防滑鼻托套装(2对装) | G12: 大号款-2.5mm | H12: 大号款 | I12: 2.5mm | J12: 2026-01-23 | K12: 2026-01 | L12: 否 | N12: Game changer for a flat nose. Glasses sit where they should. Install was simple with the little guide. | Q12: 整体高度; 安装难易 | X12: 好评
A13: 12 | B13: SAMPLE-RV-0012 | C13: 5 | D13: US | E13: 智能眼镜 硅胶防滑鼻托 背胶款 2对装 | F13: A款-防滑鼻托套装(2对装) | G13: 标准款-1.8mm | H13: 标准款 | I13: 1.8mm | J13: 2026-01-25 | K13: 2026-01 | L13: 否 | N13: So comfortable. No red marks on my nose anymore. | Q13: 佩戴舒适 | X13: 好评
A14: 13 | B14: SAMPLE-RV-0013 | C14: 4 | D14: US | E14: 智能眼镜 硅胶防滑鼻托 背胶款 2对装 | F14: A款-防滑鼻托套装(2对装) | G14: 标准款-1.8mm | H14: 标准款 | I14: 1.8mm | J14: 2026-01-27 | K14: 2026-01 | L14: 否 | N14: Does the job. Pricey for four bits of silicone but it fixed my problem. | Q14: 质量(泛指) | R14: 值不值 | V14: 说不清 | W14: 轻度 | X14: 好评
A15: 14 | B15: SAMPLE-RV-0014 | C15: 5 | D15: US | E15: 智能眼镜 硅胶防滑鼻托 背胶款 2对装 | F15: A款-防滑鼻托套装(2对装) | G15: 大号款-1.8mm | H15: 大号款 | I15: 1.8mm | J15: 2026-01-30 | K15: 2026-01 | L15: 否 | N15: Second set I have bought, one for each pair of glasses. They just work. | O15: 复购 | Q15: 质量(泛指) | X15: 好评
A16: 15 | B16: SAMPLE-RV-0020 | C16: 5 | D16: US | E16: 智能眼镜 硅胶防滑鼻托 背胶款 2对装 | F16: A款-防滑鼻托套装(2对装) | G16: 标准款-2.5mm | H16: 标准款 | I16: 2.5mm | J16: 2026-02-02 | K16: 2026-02 | L16: 否 | N16: Finally my glasses do not rest on my cheeks. The 2.5 is the right call for low bridges. | Q16: 整体高度 | X16: 好评
A17: 16 | B17: SAMPLE-RV-0021 | C17: 5 | D17: US | E17: 智能眼镜 硅胶防滑鼻托 背胶款 2对装 | F17: A款-防滑鼻托套装(2对装) | G17: 标准款-1.8mm | H17: 标准款 | I17: 1.8mm | J17: 2026-02-04 | K17: 2026-02 | L17: 否 | N17: Invisible once on. Nobody noticed. Glasses stay up when I look down. | Q17: 外观隐形; 防滑效果(泛指) | T17: 外观自然度(夸) | U17: 防滑效果(泛指)>什么场合=低头 | X17: 好评
A18: 17 | B18: SAMPLE-RV-0022 | C18: 4 | D18: US | E18: 智能眼镜 硅胶防滑鼻托 背胶款 2对装 | F18: A款-防滑鼻托套装(2对装) | G18: 标准款-1.8mm | H18: 标准款 | I18: 1.8mm | J18: 2026-02-06 | K18: 2026-02 | L18: 否 | N18: Great comfort, holds well. They are slightly wider than the stock pads, which bugs me a little. | O18: 原装鼻托 | Q18: 佩戴舒适; 防滑效果(泛指) | R18: 宽度与覆盖:偏宽 | V18: 产品的事 | W18: 轻度 | X18: 好评
A19: 18 | B19: SAMPLE-RV-0023 | C19: 1 | D19: US | E19: 智能眼镜 硅胶防滑鼻托 背胶款 2对装 | F19: A款-防滑鼻托套装(2对装) | G19: 标准款-2.5mm | H19: 标准款 | I19: 2.5mm | J19: 2026-02-08 | K19: 2026-02 | L19: 否 | N19: Way too thick. The listing told me to choose 2.5 for a low bridge and now my glasses float above my eyebrows. Returned. | O19: 照页面指引选的 | R19: 整体高度:偏高; 选档指引 | S19: 选档指引 | T19: 外观自然度 | V19: 页面的事 | W19: 中度 | X19: 差评
A20: 19 | B20: SAMPLE-RV-0024 | C20: 5 | D20: US | E20: 智能眼镜 硅胶防滑鼻托 背胶款 2对装 | F20: A款-防滑鼻托套装(2对装) | G20: 大号款-1.8mm | H20: 大号款 | I20: 1.8mm | J20: 2026-02-10 | K20: 2026-02 | L20: 否 | N20: Fits my large frames perfectly and still charges in the case. Very happy. | P20: 放回充电盒时 | Q20: 机型适配; 装上后充电; 充电盒收纳 | X20: 好评
A21: 20 | B21: SAMPLE-RV-0025 | C21: 5 | D21: US | E21: 智能眼镜 硅胶防滑鼻托 背胶款 2对装 | F21: A款-防滑鼻托套装(2对装) | G21: 标准款-2.5mm | H21: 标准款 | I21: 2.5mm | J21: 2026-02-12 | K21: 2026-02 | L21: 否 | N21: Comfortable but the glasses will not close in the charging case with these on. I take them off every night which defeats the purpose. | P21: 放回充电盒时 | Q21: 佩戴舒适 | R21: 充电盒收纳 | U21: 充电盒收纳>怎么个不行=放不进去或合不上盖 | V21: 产品的事 | W21: 中度 | X21: 差评
A22: 21 | B22: SAMPLE-RV-0026 | C22: 5 | D22: US | E22: 智能眼镜 硅胶防滑鼻托 背胶款 2对装 | F22: A款-防滑鼻托套装(2对装) | G22: 标准款-1.8mm | H22: 标准款 | I22: 1.8mm | J22: 2026-02-16 | K22: 2026-02 | L22: 否 | N22: Was using a band aid on the bridge before, embarrassing. These look clean and work. | O22: 自己垫东西 | Q22: 外观隐形; 防滑效果(泛指) | T22: 外观自然度(夸) | X22: 好评
A23: 22 | B23: SAMPLE-RV-0027 | C23: 5 | D23: US | E23: 智能眼镜 硅胶防滑鼻托 背胶款 2对装 | F23: A款-防滑鼻托套装(2对装) | G23: 标准款-1.8mm | H23: 标准款 | I23: 1.8mm | J23: 2026-02-18 | K23: 2026-02 | L23: 否 | N23: No slipping during my runs. Adhesive held through sweat so far. | P23: 运动出汗 | Q23: 出汗时防滑; 背胶牢固度 | U23: 防滑效果(泛指)>什么场合=运动 | X23: 好评
A24: 23 | B24: SAMPLE-RV-0028 | C24: 4 | D24: US | E24: 智能眼镜 硅胶防滑鼻托 背胶款 2对装 | F24: A款-防滑鼻托套装(2对装) | G24: 大号款-2.5mm | H24: 大号款 | I24: 2.5mm | J24: 2026-02-20 | K24: 2026-02 | L24: 否 | N24: Good product. Height is perfect for me. Wish they were a touch narrower. | Q24: 整体高度 | R24: 宽度与覆盖:偏宽 | V24: 产品的事 | W24: 轻度 | X24: 好评
A25: 24 | B25: SAMPLE-RV-0029 | C25: 5 | D25: US | E25: 智能眼镜 硅胶防滑鼻托 背胶款 2对装 | F25: A款-防滑鼻托套装(2对装) | G25: 标准款-1.8mm | H25: 标准款 | I25: 1.8mm | J25: 2026-02-22 | K25: 2026-02 | L25: 否 | N25: Easy install, comfortable, glasses stay put. What else do you need. | Q25: 安装难易; 佩戴舒适; 防滑效果(泛指) | X25: 好评
A26: 25 | B26: SAMPLE-RV-0030 | C26: 2 | D26: US | E26: 智能眼镜 硅胶防滑鼻托 背胶款 2对装 | F26: A款-防滑鼻托套装(2对装) | G26: 标准款-1.8mm | H26: 标准款 | I26: 1.8mm | J26: 2026-02-24 | K26: 2026-02 | L26: 否 | N26: Not enough lift for me, glasses still slide. Probably should have gone thicker. | R26: 整体高度:偏矮; 防滑效果(泛指) | U26: 防滑效果(泛指)>什么场合=没说 | V26: 客户自己选错 | W26: 轻度 | X26: 差评
A27: 26 | B27: SAMPLE-RV-0031 | C27: 5 | D27: US | E27: 智能眼镜 硅胶防滑鼻托 背胶款 2对装 | F27: A款-防滑鼻托套装(2对装) | G27: 标准款-2.5mm | H27: 标准款 | I27: 2.5mm | J27: 2026-02-26 | K27: 2026-02 | L27: 否 | N27: My dad loves them. He kept pushing his glasses up, now he doesn't. | O27: 代买(父母) | Q27: 防滑效果(泛指) | X27: 好评
A28: 27 | B28: SAMPLE-RV-0032 | C28: 4 | D28: US | E28: 智能眼镜 硅胶防滑鼻托 背胶款 2对装 | F28: A款-防滑鼻托套装(2对装) | G28: 标准款-1.8mm | H28: 标准款 | I28: 1.8mm | J28: 2026-02-27 | K28: 2026-02 | L28: 否 | N28: Works. A bit expensive. | Q28: 质量(泛指) | R28: 值不值 | V28: 说不清 | W28: 轻度 | X28: 中性
A29: 28 | B29: SAMPLE-RV-0033 | C29: 5 | D29: US | E29: 智能眼镜 硅胶防滑鼻托 背胶款 2对装 | F29: A款-防滑鼻托套装(2对装) | G29: 标准款-1.8mm | H29: 标准款 | I29: 1.8mm | J29: 2026-02-14 | K29: 2026-02 | L29: 是 | M29: 同一天同一规格 + 5 星 + 写得特别长 | N29: These nose pads are absolutely amazing and I cannot recommend them enough to everyone who owns smart glasses. The material feels premium and soft, the adhesive is incredibly strong, the height is just perfect for every nose shape, and they look completely invisible. Best purchase I have made this year without any doubt whatsoever. | Q29: 硅胶软硬; 背胶牢固度; 整体高度; 外观隐形 | X29: 好评
A30: 29 | B30: SAMPLE-RV-0034 | C30: 5 | D30: US | E30: 智能眼镜 硅胶防滑鼻托 背胶款 2对装 | F30: A款-防滑鼻托套装(2对装) | G30: 标准款-1.8mm | H30: 标准款 | I30: 1.8mm | J30: 2026-02-14 | K30: 2026-02 | L30: 是 | M30: 同一天同一规格 + 5 星 + 写得特别长 | N30: Wonderful product from a wonderful seller, I am so impressed with everything about it from the packaging to the performance. My glasses never slide anymore, the comfort is unbelievable, the quality is top notch and the price is very fair for what you get. I will be buying more sets for my whole family very soon. | Q30: 防滑效果(泛指); 佩戴舒适; 质量(泛指); 值不值 | T30: 收货第一印象(夸) | X30: 好评
A31: 30 | B31: SAMPLE-RV-0035 | C31: 5 | D31: US | E31: 智能眼镜 硅胶防滑鼻托 背胶款 2对装 | F31: A款-防滑鼻托套装(2对装) | G31: 标准款-1.8mm | H31: 标准款 | I31: 1.8mm | J31: 2026-02-14 | K31: 2026-02 | L31: 是 | M31: 同一天同一规格 + 5 星 + 写得特别长 | N31: I have tried many different nose pads for my smart glasses and nothing comes close to this set, it is simply the best on the market today. Perfect fit, perfect comfort, perfect adhesive, perfect look, there is honestly nothing I would change about it. Do yourself a favor and order these right now, you will thank me later. | O31: 其他品牌鼻托 | Q31: 佩戴舒适; 背胶牢固度; 外观隐形; 质量(泛指) | X31: 好评
A32: 31 | B32: SAMPLE-RV-0036 | C32: 5 | D32: US | E32: 智能眼镜 硅胶防滑鼻托 背胶款 2对装 | F32: A款-防滑鼻托套装(2对装) | G32: 标准款-1.8mm | H32: 标准款 | I32: 1.8mm | J32: 2026-02-14 | K32: 2026-02 | L32: 是 | M32: 同一天同一规格 + 5 星 + 写得特别长 | N32: Outstanding quality and outstanding value, this product exceeded every expectation I had and then some. Installation was effortless, the pads are soft and durable, they stay on through everything and they make my glasses feel like they were custom made for my face. Ten out of ten, a must have accessory for all smart glasses owners. | Q32: 安装难易; 硅胶软硬; 背胶牢固度; 值不值 | X32: 好评
A33: 32 | B33: SAMPLE-RV-0037 | C33: 5 | D33: US | E33: 智能眼镜 硅胶防滑鼻托 背胶款 2对装 | F33: A款-防滑鼻托套装(2对装) | G33: 标准款-1.8mm | H33: 标准款 | I33: 1.8mm | J33: 2026-03-01 | K33: 2026-03 | L33: 否 | N33: Stay put all day at work. I wear a headset too and they do not shift. | P33: 全天佩戴 | Q33: 防滑效果(泛指) | X33: 好评
A34: 33 | B34: SAMPLE-RV-0038 | C34: 4 | D34: US | E34: 智能眼镜 硅胶防滑鼻托 背胶款 2对装 | F34: A款-防滑鼻托套装(2对装) | G34: 标准款-2.5mm | H34: 标准款 | I34: 2.5mm | J34: 2026-03-03 | K34: 2026-03 | L34: 否 | N34: Height is great, comfort is great. They stick out past the nose pad a bit, visible from the front in bright light. | Q34: 整体高度; 佩戴舒适 | R34: 宽度与覆盖:偏宽; 外观隐形 | V34: 产品的事 | W34: 轻度 | X34: 好评
A35: 34 | B35: SAMPLE-RV-0039 | C35: 5 | D35: US | E35: 智能眼镜 硅胶防滑鼻托 背胶款 2对装 | F35: A款-防滑鼻托套装(2对装) | G35: 大号款-1.8mm | H35: 大号款 | I35: 1.8mm | J35: 2026-03-05 | K35: 2026-03 | L35: 否 | N35: Comfortable and they fit my large frames. Charging case closes fine. | P35: 放回充电盒时 | Q35: 佩戴舒适; 机型适配; 充电盒收纳 | X35: 好评
A36: 35 | B36: SAMPLE-RV-0040 | C36: 2 | D36: US | E36: 智能眼镜 硅胶防滑鼻托 背胶款 2对装 | F36: A款-防滑鼻托套装(2对装) | G36: 标准款-2.5mm | H36: 标准款 | I36: 2.5mm | J36: 2026-03-08 | K36: 2026-03 | L36: 否 | N36: Does not fit in the charging case. Had to choose between charging my glasses and wearing the pads. | P36: 放回充电盒时 | R36: 充电盒收纳 | U36: 充电盒收纳>怎么个不行=放不进去或合不上盖 | V36: 产品的事 | W36: 中度 | X36: 差评
A37: 36 | B37: SAMPLE-RV-0041 | C37: 5 | D37: US | E37: 智能眼镜 硅胶防滑鼻托 背胶款 2对装 | F37: A款-防滑鼻托套装(2对装) | G37: 标准款-1.8mm | H37: 标准款 | I37: 1.8mm | J37: 2026-03-10 | K37: 2026-03 | L37: 否 | N37: Simple fix for a real problem. No more sliding when I cook or look down. | Q37: 防滑效果(泛指) | U37: 防滑效果(泛指)>什么场合=低头 | X37: 好评
A38: 37 | B38: SAMPLE-RV-0042 | C38: 3 | D38: US | E38: 智能眼镜 硅胶防滑鼻托 背胶款 2对装 | F38: A款-防滑鼻托套装(2对装) | G38: 大号款-2.5mm | H38: 大号款 | I38: 2.5mm | J38: 2026-03-12 | K38: 2026-03 | L38: 否 | N38: Stops the slide. But the pads are wider than the frame pad and it looks like I stuck tape on my glasses. Function over form I guess. | Q38: 防滑效果(泛指) | R38: 宽度与覆盖:偏宽; 外观隐形 | T38: 外观自然度 | V38: 产品的事 | W38: 中度 | X38: 中性
A39: 38 | B39: SAMPLE-RV-0043 | C39: 5 | D39: US | E39: 智能眼镜 硅胶防滑鼻托 背胶款 2对装 | F39: A款-防滑鼻托套装(2对装) | G39: 标准款-1.8mm | H39: 标准款 | I39: 1.8mm | J39: 2026-03-15 | K39: 2026-03 | L39: 否 | N39: Soft, clear, and comfy. Took them off once to reposition and they came off clean, no residue. | Q39: 硅胶软硬; 佩戴舒适; 撕下后留胶 | X39: 好评
A40: 39 | B40: SAMPLE-RV-0044 | C40: 5 | D40: US | E40: 智能眼镜 硅胶防滑鼻托 背胶款 2对装 | F40: A款-防滑鼻托套装(2对装) | G40: 标准款-2.5mm | H40: 标准款 | I40: 2.5mm | J40: 2026-03-18 | K40: 2026-03 | L40: 否 | N40: I have a very flat bridge and these are the first thing that worked. Love them. | Q40: 整体高度 | X40: 好评
...

Sheet 哪件事提得多满不满意
A1: 横着是提到多少次，竖着是好评占比
A2: 门槛跟着数据量走：进排名 ≥5 次；横向分界 6 次（全部标签提及的中位数）；纵向分界 63.3%（加权平均好评占比）
A4: 细项 | B4: 提到次数 | C4: 好评次数 | D4: 差评次数 | E4: 好评占比 | F4: 落在哪一块
A5: 防滑效果(泛指) | B5: =C5+D5 | C5: =COUNTIF(打标明细!Q:Q,"*防滑效果(泛指)*") | D5: =COUNTIF(打标明细!R:R,"*防滑效果(泛指)*") | E5: =IFERROR(C5/B5,"") | F5: =IF(B5<5,"没进排名（提得太少）",IF(B5>=6,IF(E5<0.6332,"★ 提得多又不满意 · 该先动","提得多也满意 · 已经赢了"),IF(E5<0.6332,"提得少不满意 · 盯着","提得少但满意")))
A6: 佩戴舒适 | B6: =C6+D6 | C6: =COUNTIF(打标明细!Q:Q,"*佩戴舒适*") | D6: =COUNTIF(打标明细!R:R,"*佩戴舒适*") | E6: =IFERROR(C6/B6,"") | F6: =IF(B6<5,"没进排名（提得太少）",IF(B6>=6,IF(E6<0.6332,"★ 提得多又不满意 · 该先动","提得多也满意 · 已经赢了"),IF(E6<0.6332,"提得少不满意 · 盯着","提得少但满意")))
A7: 背胶牢固度 | B7: =C7+D7 | C7: =COUNTIF(打标明细!Q:Q,"*背胶牢固度*") | D7: =COUNTIF(打标明细!R:R,"*背胶牢固度*") | E7: =IFERROR(C7/B7,"") | F7: =IF(B7<5,"没进排名（提得太少）",IF(B7>=6,IF(E7<0.6332,"★ 提得多又不满意 · 该先动","提得多也满意 · 已经赢了"),IF(E7<0.6332,"提得少不满意 · 盯着","提得少但满意")))
A8: 整体高度 | B8: =C8+D8 | C8: =COUNTIF(打标明细!Q:Q,"*整体高度*") | D8: =COUNTIF(打标明细!R:R,"*整体高度*") | E8: =IFERROR(C8/B8,"") | F8: =IF(B8<5,"没进排名（提得太少）",IF(B8>=6,IF(E8<0.6332,"★ 提得多又不满意 · 该先动","提得多也满意 · 已经赢了"),IF(E8<0.6332,"提得少不满意 · 盯着","提得少但满意")))
A9: 充电盒收纳 | B9: =C9+D9 | C9: =COUNTIF(打标明细!Q:Q,"*充电盒收纳*") | D9: =COUNTIF(打标明细!R:R,"*充电盒收纳*") | E9: =IFERROR(C9/B9,"") | F9: =IF(B9<5,"没进排名（提得太少）",IF(B9>=6,IF(E9<0.6332,"★ 提得多又不满意 · 该先动","提得多也满意 · 已经赢了"),IF(E9<0.6332,"提得少不满意 · 盯着","提得少但满意")))
A10: 外观隐形 | B10: =C10+D10 | C10: =COUNTIF(打标明细!Q:Q,"*外观隐形*") | D10: =COUNTIF(打标明细!R:R,"*外观隐形*") | E10: =IFERROR(C10/B10,"") | F10: =IF(B10<5,"没进排名（提得太少）",IF(B10>=6,IF(E10<0.6332,"★ 提得多又不满意 · 该先动","提得多也满意 · 已经赢了"),IF(E10<0.6332,"提得少不满意 · 盯着","提得少但满意")))
A11: 宽度与覆盖 | B11: =C11+D11 | C11: =COUNTIF(打标明细!Q:Q,"*宽度与覆盖*") | D11: =COUNTIF(打标明细!R:R,"*宽度与覆盖*") | E11: =IFERROR(C11/B11,"") | F11: =IF(B11<5,"没进排名（提得太少）",IF(B11>=6,IF(E11<0.6332,"★ 提得多又不满意 · 该先动","提得多也满意 · 已经赢了"),IF(E11<0.6332,"提得少不满意 · 盯着","提得少但满意")))
A12: 质量(泛指) | B12: =C12+D12 | C12: =COUNTIF(打标明细!Q:Q,"*质量(泛指)*") | D12: =COUNTIF(打标明细!R:R,"*质量(泛指)*") | E12: =IFERROR(C12/B12,"") | F12: =IF(B12<5,"没进排名（提得太少）",IF(B12>=6,IF(E12<0.6332,"★ 提得多又不满意 · 该先动","提得多也满意 · 已经赢了"),IF(E12<0.6332,"提得少不满意 · 盯着","提得少但满意")))
A13: 值不值 | B13: =C13+D13 | C13: =COUNTIF(打标明细!Q:Q,"*值不值*") | D13: =COUNTIF(打标明细!R:R,"*值不值*") | E13: =IFERROR(C13/B13,"") | F13: =IF(B13<5,"没进排名（提得太少）",IF(B13>=6,IF(E13<0.6332,"★ 提得多又不满意 · 该先动","提得多也满意 · 已经赢了"),IF(E13<0.6332,"提得少不满意 · 盯着","提得少但满意")))
A14: 硅胶软硬 | B14: =C14+D14 | C14: =COUNTIF(打标明细!Q:Q,"*硅胶软硬*") | D14: =COUNTIF(打标明细!R:R,"*硅胶软硬*") | E14: =IFERROR(C14/B14,"") | F14: =IF(B14<5,"没进排名（提得太少）",IF(B14>=6,IF(E14<0.6332,"★ 提得多又不满意 · 该先动","提得多也满意 · 已经赢了"),IF(E14<0.6332,"提得少不满意 · 盯着","提得少但满意")))
A15: 安装难易 | B15: =C15+D15 | C15: =COUNTIF(打标明细!Q:Q,"*安装难易*") | D15: =COUNTIF(打标明细!R:R,"*安装难易*") | E15: =IFERROR(C15/B15,"") | F15: =IF(B15<5,"没进排名（提得太少）",IF(B15>=6,IF(E15<0.6332,"★ 提得多又不满意 · 该先动","提得多也满意 · 已经赢了"),IF(E15<0.6332,"提得少不满意 · 盯着","提得少但满意")))
A16: 机型适配 | B16: =C16+D16 | C16: =COUNTIF(打标明细!Q:Q,"*机型适配*") | D16: =COUNTIF(打标明细!R:R,"*机型适配*") | E16: =IFERROR(C16/B16,"") | F16: =IF(B16<5,"没进排名（提得太少）",IF(B16>=6,IF(E16<0.6332,"★ 提得多又不满意 · 该先动","提得多也满意 · 已经赢了"),IF(E16<0.6332,"提得少不满意 · 盯着","提得少但满意")))
A17: 出汗时防滑 | B17: =C17+D17 | C17: =COUNTIF(打标明细!Q:Q,"*出汗时防滑*") | D17: =COUNTIF(打标明细!R:R,"*出汗时防滑*") | E17: =IFERROR(C17/B17,"") | F17: =IF(B17<5,"没进排名（提得太少）",IF(B17>=6,IF(E17<0.6332,"★ 提得多又不满意 · 该先动","提得多也满意 · 已经赢了"),IF(E17<0.6332,"提得少不满意 · 盯着","提得少但满意")))
A18: 同款批次一致性 | B18: =C18+D18 | C18: =COUNTIF(打标明细!Q:Q,"*同款批次一致性*") | D18: =COUNTIF(打标明细!R:R,"*同款批次一致性*") | E18: =IFERROR(C18/B18,"") | F18: =IF(B18<5,"没进排名（提得太少）",IF(B18>=6,IF(E18<0.6332,"★ 提得多又不满意 · 该先动","提得多也满意 · 已经赢了"),IF(E18<0.6332,"提得少不满意 · 盯着","提得少但满意")))
A19: 撕下后留胶 | B19: =C19+D19 | C19: =COUNTIF(打标明细!Q:Q,"*撕下后留胶*") | D19: =COUNTIF(打标明细!R:R,"*撕下后留胶*") | E19: =IFERROR(C19/B19,"") | F19: =IF(B19<5,"没进排名（提得太少）",IF(B19>=6,IF(E19<0.6332,"★ 提得多又不满意 · 该先动","提得多也满意 · 已经赢了"),IF(E19<0.6332,"提得少不满意 · 盯着","提得少但满意")))
A20: 装上后充电 | B20: =C20+D20 | C20: =COUNTIF(打标明细!Q:Q,"*装上后充电*") | D20: =COUNTIF(打标明细!R:R,"*装上后充电*") | E20: =IFERROR(C20/B20,"") | F20: =IF(B20<5,"没进排名（提得太少）",IF(B20>=6,IF(E20<0.6332,"★ 提得多又不满意 · 该先动","提得多也满意 · 已经赢了"),IF(E20<0.6332,"提得少不满意 · 盯着","提得少但满意")))
A21: 防滑宣称兑现度 | B21: =C21+D21 | C21: =COUNTIF(打标明细!Q:Q,"*防滑宣称兑现度*") | D21: =COUNTIF(打标明细!R:R,"*防滑宣称兑现度*") | E21: =IFERROR(C21/B21,"") | F21: =IF(B21<5,"没进排名（提得太少）",IF(B21>=6,IF(E21<0.6332,"★ 提得多又不满意 · 该先动","提得多也满意 · 已经赢了"),IF(E21<0.6332,"提得少不满意 · 盯着","提得少但满意")))
A22: 摄像头视角 | B22: =C22+D22 | C22: =COUNTIF(打标明细!Q:Q,"*摄像头视角*") | D22: =COUNTIF(打标明细!R:R,"*摄像头视角*") | E22: =IFERROR(C22/B22,"") | F22: =IF(B22<5,"没进排名（提得太少）",IF(B22>=6,IF(E22<0.6332,"★ 提得多又不满意 · 该先动","提得多也满意 · 已经赢了"),IF(E22<0.6332,"提得少不满意 · 盯着","提得少但满意")))
A23: 耐黄变 | B23: =C23+D23 | C23: =COUNTIF(打标明细!Q:Q,"*耐黄变*") | D23: =COUNTIF(打标明细!R:R,"*耐黄变*") | E23: =IFERROR(C23/B23,"") | F23: =IF(B23<5,"没进排名（提得太少）",IF(B23>=6,IF(E23<0.6332,"★ 提得多又不满意 · 该先动","提得多也满意 · 已经赢了"),IF(E23<0.6332,"提得少不满意 · 盯着","提得少但满意")))
A24: 选档指引 | B24: =C24+D24 | C24: =COUNTIF(打标明细!Q:Q,"*选档指引*") | D24: =COUNTIF(打标明细!R:R,"*选档指引*") | E24: =IFERROR(C24/B24,"") | F24: =IF(B24<5,"没进排名（提得太少）",IF(B24>=6,IF(E24<0.6332,"★ 提得多又不满意 · 该先动","提得多也满意 · 已经赢了"),IF(E24<0.6332,"提得少不满意 · 盯着","提得少但满意")))

Sheet 差评最多的事
A1: 差评最多的事（直接对应行动）
A3: 细项 | B3: 差评次数 | C3: 占全部评论 | D3: 其中严重 | E3: 哪个部门
A4: 背胶牢固度 | B4: =COUNTIF(打标明细!R:R,"*背胶牢固度*") | C4: =IFERROR(B4/(COUNTA(打标明细!A:A)-1),"") | D4: =COUNTIFS(打标明细!R:R,"*背胶牢固度*",打标明细!W:W,"严重") | E4: 产品 · 材料
A5: 宽度与覆盖 | B5: =COUNTIF(打标明细!R:R,"*宽度与覆盖*") | C5: =IFERROR(B5/(COUNTA(打标明细!A:A)-1),"") | D5: =COUNTIFS(打标明细!R:R,"*宽度与覆盖*",打标明细!W:W,"严重") | E5: 产品 · 结构
A6: 充电盒收纳 | B6: =COUNTIF(打标明细!R:R,"*充电盒收纳*") | C6: =IFERROR(B6/(COUNTA(打标明细!A:A)-1),"") | D6: =COUNTIFS(打标明细!R:R,"*充电盒收纳*",打标明细!W:W,"严重") | E6: 运营 · 页面 / 产品 · 结构
A7: 外观隐形 | B7: =COUNTIF(打标明细!R:R,"*外观隐形*") | C7: =IFERROR(B7/(COUNTA(打标明细!A:A)-1),"") | D7: =COUNTIFS(打标明细!R:R,"*外观隐形*",打标明细!W:W,"严重") | E7: 产品 · 结构
A8: 值不值 | B8: =COUNTIF(打标明细!R:R,"*值不值*") | C8: =IFERROR(B8/(COUNTA(打标明细!A:A)-1),"") | D8: =COUNTIFS(打标明细!R:R,"*值不值*",打标明细!W:W,"严重") | E8: 定价
A9: 整体高度 | B9: =COUNTIF(打标明细!R:R,"*整体高度*") | C9: =IFERROR(B9/(COUNTA(打标明细!A:A)-1),"") | D9: =COUNTIFS(打标明细!R:R,"*整体高度*",打标明细!W:W,"严重") | E9: 运营 · 页面（选档说明）
A10: 同款批次一致性 | B10: =COUNTIF(打标明细!R:R,"*同款批次一致性*") | C10: =IFERROR(B10/(COUNTA(打标明细!A:A)-1),"") | D10: =COUNTIFS(打标明细!R:R,"*同款批次一致性*",打标明细!W:W,"严重") | E10: 产品 · 研发/品控
A11: 摄像头视角 | B11: =COUNTIF(打标明细!R:R,"*摄像头视角*") | C11: =IFERROR(B11/(COUNTA(打标明细!A:A)-1),"") | D11: =COUNTIFS(打标明细!R:R,"*摄像头视角*",打标明细!W:W,"严重") | E11: 产品 · 研发/品控
A12: 硅胶软硬 | B12: =COUNTIF(打标明细!R:R,"*硅胶软硬*") | C12: =IFERROR(B12/(COUNTA(打标明细!A:A)-1),"") | D12: =COUNTIFS(打标明细!R:R,"*硅胶软硬*",打标明细!W:W,"严重") | E12: 产品 · 研发/品控
A13: 耐黄变 | B13: =COUNTIF(打标明细!R:R,"*耐黄变*") | C13: =IFERROR(B13/(COUNTA(打标明细!A:A)-1),"") | D13: =COUNTIFS(打标明细!R:R,"*耐黄变*",打标明细!W:W,"严重") | E13: 产品 · 材料
A14: 防滑宣称兑现度 | B14: =COUNTIF(打标明细!R:R,"*防滑宣称兑现度*") | C14: =IFERROR(B14/(COUNTA(打标明细!A:A)-1),"") | D14: =COUNTIFS(打标明细!R:R,"*防滑宣称兑现度*",打标明细!W:W,"严重") | E14: 运营 · 页面
A15: 撕下后留胶 | B15: =COUNTIF(打标明细!R:R,"*撕下后留胶*") | C15: =IFERROR(B15/(COUNTA(打标明细!A:A)-1),"") | D15: =COUNTIFS(打标明细!R:R,"*撕下后留胶*",打标明细!W:W,"严重") | E15: 产品 · 材料
A16: 装上后充电 | B16: =COUNTIF(打标明细!R:R,"*装上后充电*") | C16: =IFERROR(B16/(COUNTA(打标明细!A:A)-1),"") | D16: =COUNTIFS(打标明细!R:R,"*装上后充电*",打标明细!W:W,"严重") | E16: 产品 · 结构
A17: 选档指引 | B17: =COUNTIF(打标明细!R:R,"*选档指引*") | C17: =IFERROR(B17/(COUNTA(打标明细!A:A)-1),"") | D17: =COUNTIFS(打标明细!R:R,"*选档指引*",打标明细!W:W,"严重") | E17: 运营 · 页面
A18: 防滑效果(泛指) | B18: =COUNTIF(打标明细!R:R,"*防滑效果(泛指)*") | C18: =IFERROR(B18/(COUNTA(打标明细!A:A)-1),"") | D18: =COUNTIFS(打标明细!R:R,"*防滑效果(泛指)*",打标明细!W:W,"严重") | E18: 不算产品问题

Sheet 交叉分析
A1: 分组看好评占比（好评占比 = 这一组里整体是好评的条数 ÷ 这一组的条数）｜分组小的只看方向
A3: 按适配机型
A4: 分组 | B4: 条数 | C4: 好评 | D4: 差评 | E4: 好评占比
A5: 标准款 | B5: =COUNTIF(打标明细!H:H,A5) | C5: =COUNTIFS(打标明细!H:H,A5,打标明细!X:X,"好评") | D5: =COUNTIFS(打标明细!H:H,A5,打标明细!X:X,"差评") | E5: =IFERROR(C5/B5,"")
A6: 大号款 | B6: =COUNTIF(打标明细!H:H,A6) | C6: =COUNTIFS(打标明细!H:H,A6,打标明细!X:X,"好评") | D6: =COUNTIFS(打标明细!H:H,A6,打标明细!X:X,"差评") | E6: =IFERROR(C6/B6,"")
A8: 按高度档
A9: 分组 | B9: 条数 | C9: 好评 | D9: 差评 | E9: 好评占比
A10: 1.8mm | B10: =COUNTIF(打标明细!I:I,A10) | C10: =COUNTIFS(打标明细!I:I,A10,打标明细!X:X,"好评") | D10: =COUNTIFS(打标明细!I:I,A10,打标明细!X:X,"差评") | E10: =IFERROR(C10/B10,"")
A11: 2.5mm | B11: =COUNTIF(打标明细!I:I,A11) | C11: =COUNTIFS(打标明细!I:I,A11,打标明细!X:X,"好评") | D11: =COUNTIFS(打标明细!I:I,A11,打标明细!X:X,"差评") | E11: =IFERROR(C11/B11,"")
A13: 按规格
A14: 分组 | B14: 条数 | C14: 好评 | D14: 差评 | E14: 好评占比
A15: 标准款-1.8mm | B15: =COUNTIF(打标明细!G:G,A15) | C15: =COUNTIFS(打标明细!G:G,A15,打标明细!X:X,"好评") | D15: =COUNTIFS(打标明细!G:G,A15,打标明细!X:X,"差评") | E15: =IFERROR(C15/B15,"")
A16: 标准款-2.5mm | B16: =COUNTIF(打标明细!G:G,A16) | C16: =COUNTIFS(打标明细!G:G,A16,打标明细!X:X,"好评") | D16: =COUNTIFS(打标明细!G:G,A16,打标明细!X:X,"差评") | E16: =IFERROR(C16/B16,"")
A17: 大号款-1.8mm | B17: =COUNTIF(打标明细!G:G,A17) | C17: =COUNTIFS(打标明细!G:G,A17,打标明细!X:X,"好评") | D17: =COUNTIFS(打标明细!G:G,A17,打标明细!X:X,"差评") | E17: =IFERROR(C17/B17,"")
A18: 大号款-2.5mm | B18: =COUNTIF(打标明细!G:G,A18) | C18: =COUNTIFS(打标明细!G:G,A18,打标明细!X:X,"好评") | D18: =COUNTIFS(打标明细!G:G,A18,打标明细!X:X,"差评") | E18: =IFERROR(C18/B18,"")
A20: 按疑似不可信
A21: 分组 | B21: 条数 | C21: 好评 | D21: 差评 | E21: 好评占比
A22: 否 | B22: =COUNTIF(打标明细!L:L,A22) | C22: =COUNTIFS(打标明细!L:L,A22,打标明细!X:X,"好评") | D22: =COUNTIFS(打标明细!L:L,A22,打标明细!X:X,"差评") | E22: =IFERROR(C22/B22,"")
A23: 是 | B23: =COUNTIF(打标明细!L:L,A23) | C23: =COUNTIFS(打标明细!L:L,A23,打标明细!X:X,"好评") | D23: =COUNTIFS(打标明细!L:L,A23,打标明细!X:X,"差评") | E23: =IFERROR(C23/B23,"")

Sheet 按月走势
A1: 按月走势（共 92 条，条数少的月份只看方向）
A3: 月份 | B3: 条数 | C3: 其中疑似刷的 | D3: 好评 | E3: 差评 | F3: 好评占比 | G3: 平均星级
A4: 2026-01 | B4: =COUNTIF(打标明细!K:K,A4) | C4: =COUNTIFS(打标明细!K:K,A4,打标明细!L:L,"是") | D4: =COUNTIFS(打标明细!K:K,A4,打标明细!X:X,"好评") | E4: =COUNTIFS(打标明细!K:K,A4,打标明细!X:X,"差评") | F4: =IFERROR(D4/B4,"") | G4: =IFERROR(AVERAGEIFS(打标明细!C:C,打标明细!K:K,A4),"")
A5: 2026-02 | B5: =COUNTIF(打标明细!K:K,A5) | C5: =COUNTIFS(打标明细!K:K,A5,打标明细!L:L,"是") | D5: =COUNTIFS(打标明细!K:K,A5,打标明细!X:X,"好评") | E5: =COUNTIFS(打标明细!K:K,A5,打标明细!X:X,"差评") | F5: =IFERROR(D5/B5,"") | G5: =IFERROR(AVERAGEIFS(打标明细!C:C,打标明细!K:K,A5),"")
A6: 2026-03 | B6: =COUNTIF(打标明细!K:K,A6) | C6: =COUNTIFS(打标明细!K:K,A6,打标明细!L:L,"是") | D6: =COUNTIFS(打标明细!K:K,A6,打标明细!X:X,"好评") | E6: =COUNTIFS(打标明细!K:K,A6,打标明细!X:X,"差评") | F6: =IFERROR(D6/B6,"") | G6: =IFERROR(AVERAGEIFS(打标明细!C:C,打标明细!K:K,A6),"")
A7: 2026-04 | B7: =COUNTIF(打标明细!K:K,A7) | C7: =COUNTIFS(打标明细!K:K,A7,打标明细!L:L,"是") | D7: =COUNTIFS(打标明细!K:K,A7,打标明细!X:X,"好评") | E7: =COUNTIFS(打标明细!K:K,A7,打标明细!X:X,"差评") | F7: =IFERROR(D7/B7,"") | G7: =IFERROR(AVERAGEIFS(打标明细!C:C,打标明细!K:K,A7),"")
A8: 2026-05 | B8: =COUNTIF(打标明细!K:K,A8) | C8: =COUNTIFS(打标明细!K:K,A8,打标明细!L:L,"是") | D8: =COUNTIFS(打标明细!K:K,A8,打标明细!X:X,"好评") | E8: =COUNTIFS(打标明细!K:K,A8,打标明细!X:X,"差评") | F8: =IFERROR(D8/B8,"") | G8: =IFERROR(AVERAGEIFS(打标明细!C:C,打标明细!K:K,A8),"")
A9: 2026-06 | B9: =COUNTIF(打标明细!K:K,A9) | C9: =COUNTIFS(打标明细!K:K,A9,打标明细!L:L,"是") | D9: =COUNTIFS(打标明细!K:K,A9,打标明细!X:X,"好评") | E9: =COUNTIFS(打标明细!K:K,A9,打标明细!X:X,"差评") | F9: =IFERROR(D9/B9,"") | G9: =IFERROR(AVERAGEIFS(打标明细!C:C,打标明细!K:K,A9),"")
A10: 2026-07 | B10: =COUNTIF(打标明细!K:K,A10) | C10: =COUNTIFS(打标明细!K:K,A10,打标明细!L:L,"是") | D10: =COUNTIFS(打标明细!K:K,A10,打标明细!X:X,"好评") | E10: =COUNTIFS(打标明细!K:K,A10,打标明细!X:X,"差评") | F10: =IFERROR(D10/B10,"") | G10: =IFERROR(AVERAGEIFS(打标明细!C:C,打标明细!K:K,A10),"")
A11: 2026-08 | B11: =COUNTIF(打标明细!K:K,A11) | C11: =COUNTIFS(打标明细!K:K,A11,打标明细!L:L,"是") | D11: =COUNTIFS(打标明细!K:K,A11,打标明细!X:X,"好评") | E11: =COUNTIFS(打标明细!K:K,A11,打标明细!X:X,"差评") | F11: =IFERROR(D11/B11,"") | G11: =IFERROR(AVERAGEIFS(打标明细!C:C,打标明细!K:K,A11),"")

Sheet 再问一层
A1: 往下再问一层（要问什么，打标的时候就留好了位置）｜「没说」的占比本身就是结论
A3: 防滑效果(泛指) · 什么场合
A4: 答案 | B4: 条数 | C4: 占这一问
A5: 低头 | B5: 3 | C5: =IFERROR(B5/7,"")
A6: 运动 | B6: 3 | C6: =IFERROR(B6/7,"")
A7: 没说 | B7: 1 | C7: =IFERROR(B7/7,"")
A9: 充电盒收纳 · 怎么个不行
A10: 答案 | B10: 条数 | C10: 占这一问
A11: 放不进去或合不上盖 | B11: 9 | C11: =IFERROR(B11/9,"")
A13: 背胶牢固度 · 多久出的问题
A14: 答案 | B14: 条数 | C14: 占这一问
A15: 一周内 | B15: 11 | C15: =IFERROR(B15/20,"")
A16: 没说 | B16: 8 | C16: =IFERROR(B16/20,"")
A17: 第一天 | B17: 1 | C17: =IFERROR(B17/20,"")
A19: 背胶牢固度 · 什么场合
A20: 答案 | B20: 条数 | C20: 占这一问
A21: 没说 | B21: 12 | C21: =IFERROR(B21/20,"")
A22: 出汗 | B22: 5 | C22: =IFERROR(B22/20,"")
A23: 日常佩戴 | B23: 2 | C23: =IFERROR(B23/20,"")
A24: 放充电盒时 | B24: 1 | C24: =IFERROR(B24/20,"")

Sheet 结论对原话
A1: 每个结论对应哪几条原话（序号对应「打标明细」）
A3: 结论 | B3: 原话（节选） | C3: 序号 | D3: 星级
A4: 背胶是 5 月以后才坏的 | B4: Used to love these, this is my third order. The latest ones are stiffer and do not stick like before. | C4: 83 | D4: 2
A5: 宽度一边倒 | B5: Stops the slide. But the pads are wider than the frame pad and it looks like I stuck tape on my glasses. | C5: 37 | D5: 3
A6: 2.5mm 放不回充电盒 | B6: Glasses won't fit the case with the 2.5 pads. The photos show them in the case so I assumed it would work. | C6: 48 | D6: 2
A7: 星级和文字对不上，以文字为准 | B7: Comfortable but the glasses will not close in the charging case with these on. I take them off every night which defeats the purpose. | C7: 20 | D7: 5

Sheet 说明与口径
A1: A款-防滑鼻托套装(2对装)｜评论分析 · 说明与口径
A3: 数据处理记录
A4: 品类 | B4: AI 眼镜配件
A5: 配置版本 | B5: v0.2
A6: 文件编码 | B6: utf-8-sig
A7: 原始条数 | B7: 97
A8: 剔掉送测 | B8: 5
A9: 剔掉没写字的 | B9: 0
A10: 进入分析 | B10: 92
A11: 疑似刷的 | B11: 4
A12: 差评占比_1到2星 | B12: 0.25
A13: 平均星级 | B13: 3.78
A15: 门槛与分界 | B15: 进排名 ≥5 次 · 横向 6 次 · 纵向 63.3%
A16: 去掉疑似刷的之后 | B16: 整体好评占比 64.1% → 62.5%
... A18: 已经赢了的 | B18: 防滑效果(泛指) · 佩戴舒适 · 整体高度 · 质量(泛指) · 硅胶软硬
A20: 这批数据答不了什么
B21: 92 条，属于「可以判方向」这一档（不到 30 条只读不算；50–200 条判方向；200 条以上才做细分对比）。所有分组里最小的一格只有几条，比例不能当定量结论用。
B22: 疑似刷的评论 4 条（同一天、同一规格、5 星、写得特别长），只标记没有删。去掉之后整体好评占比从 64.1% 变成 62.5%，结论方向不变。
B23: 有 1 条 5 星评论，正文是差评（放不回充电盒、「defeats the purpose」）。好坏以文字为准，这一条按差评算。
B24: 背胶的下钻里，「多久出的问题」40% 没说，「什么场合」60% 没说。评论这份数据在「为什么掉」上到此为止，已写进行动清单去补。
B25: 7 月、8 月各只有 9 条、8 条，按月比例不稳，只看方向。
B26: 整体高度在评论里是 4 条嫌高、1 条嫌矮，样本太少，不下结论；这一项以退货那边的 15 比 16 为准。
B27: 退货那份数据只当独立佐证用，没有和评论混在一起算任何一个比例。
B28: 被页面那句选档建议坑到的人，在退货里有 6 条，在评论里只有 1 条——买了不满意的人多数不写评论，直接退了。只看评论会低估这件事。
